Workbook

Sheet C39
B1: =VLOOKUP(A5,'PMC数据辅助&月良率预估'!$AR$3:$AS$130,2,0) -> 折叠 | C1: 0.88 | E1: A1
A2: =VLOOKUP(A5,切数!$C:$J,8,0) -> 45 | B2: 辅助列 | D2: 已生产批次 | E2: 月预估=当月各批次良率加权
A3: 预估月 | E3: =_xlfn.IFNA(VLOOKUP($A$5&E$4,'PMC数据辅助&月良率预估'!$B$2:$G$1000,2,0),"") -> M06 | J3: =_xlfn.IFNA(VLOOKUP($A$5&J$4,'PMC数据辅助&月良率预估'!$B$2:$G$1000,2,0),"") | O3: =_xlfn.IFNA(VLOOKUP($A$5&O$4,'PMC数据辅助&月良率预估'!$B$2:$G$1000,2,0),"") | T3: =_xlfn.IFNA(VLOOKUP($A$5&T$4,'PMC数据辅助&月良率预估'!$B$2:$G$1000,2,0),"") | Y3: =_xlfn.IFNA(VLOOKUP($A$5&Y$4,'PMC数据辅助&月良率预估'!$B$2:$G$1000,2,0),"") | AD3: =_xlfn.IFNA(VLOOKUP($A$5&AD$4,'PMC数据辅助&月良率预估'!$B$2:$G$1000,2,0),"") | AI3: =_xlfn.IFNA(VLOOKUP($A$5&AI$4,'PMC数据辅助&月良率预估'!$B$2:$G$1000,2,0),"") | AN3: =_xlfn.IFNA(VLOOKUP($A$5&AN$4,'PMC数据辅助&月良率预估'!$B$2:$G$1000,2,0),"") | AS3: =_xlfn.IFNA(VLOOKUP($A$5&AS$4,'PMC数据辅助&月良率预估'!$B$2:$G$1000,2,0),"") | AX3: =_xlfn.IFNA(VLOOKUP($A$5&AX$4,'PMC数据辅助&月良率预估'!$B$2:$G$1000,2,0),"") | BC3: =_xlfn.IFNA(VLOOKUP($A$5&BC$4,'PMC数据辅助&月良率预估'!$B$2:$G$1000,2,0),"") | BH3: =_xlfn.IFNA(VLOOKUP($A$5&BH$4,'PMC数据辅助&月良率预估'!$B$2:$G$1000,2,0),"") | BM3: =_xlfn.IFNA(VLOOKUP($A$5&BM$4,'PMC数据辅助&月良率预估'!$B$2:$G$1000,2,0),"")
A4: 蒸镀批次 | B4: 25/11/26蒸镀批 | C4: 25/12/27蒸镀批 | E4: =_xlfn.IFNA(VLOOKUP($A$5&COLUMN($A$1),'PMC数据辅助&月良率预估'!$A:$F,5,0),"") -> 06/18蒸镀批次 | J4: =_xlfn.IFNA(VLOOKUP($A$5&COLUMN($B$1),'PMC数据辅助&月良率预估'!$A:$F,5,0),"") | O4: =_xlfn.IFNA(VLOOKUP($A$5&COLUMN($C$1),'PMC数据辅助&月良率预估'!$A:$F,5,0),"") | T4: =_xlfn.IFNA(VLOOKUP($A$5&COLUMN($D$1),'PMC数据辅助&月良率预估'!$A:$F,5,0),"") | Y4: =_xlfn.IFNA(VLOOKUP($A$5&COLUMN($E$1),'PMC数据辅助&月良率预估'!$A:$F,5,0),"") | AD4: =_xlfn.IFNA(VLOOKUP($A$5&COLUMN($F$1),'PMC数据辅助&月良率预估'!$A:$F,5,0),"") | AI4: =_xlfn.IFNA(VLOOKUP($A$5&COLUMN($G$1),'PMC数据辅助&月良率预估'!$A:$F,5,0),"") | AN4: =_xlfn.IFNA(VLOOKUP($A$5&COLUMN($H$1),'PMC数据辅助&月良率预估'!$A:$F,5,0),"") | AS4: =_xlfn.IFNA(VLOOKUP($A$5&COLUMN($I$1),'PMC数据辅助&月良率预估'!$A:$F,5,0),"") | AX4: =_xlfn.IFNA(VLOOKUP($A$5&COLUMN($J$1),'PMC数据辅助&月良率预估'!$A:$F,5,0),"") | BC4: =_xlfn.IFNA(VLOOKUP($A$5&COLUMN($K$1),'PMC数据辅助&月良率预估'!$A:$F,5,0),"") | BH4: =_xlfn.IFNA(VLOOKUP($A$5&COLUMN($L$1),'PMC数据辅助&月良率预估'!$A:$F,5,0),"") | BM4: =_xlfn.IFNA(VLOOKUP($A$5&COLUMN($M$1),'PMC数据辅助&月良率预估'!$A:$F,5,0),"")
A5: C39 | B5: 不良率 | C5: 不良率 | E5: 对策合入/异常影响 | F5: 良率正贡献 （贡献加和值） | G5: 良率负影响 （影响加和值） | H5: 不良预估 现状-正贡献+负影响 | I5: Inline佐证数据 | J5: 对策合入/异常影响 | K5: 良率正贡献 （贡献加和值） | L5: 良率负影响 （影响加和值） | M5: 不良预估 现状-正贡献+负影响 | N5: Inline佐证数据 | O5: 对策合入/异常影响 | P5: 良率正贡献 （贡献加和值） | Q5: 良率负影响 （影响加和值） | R5: 不良预估 现状-正贡献+负影响 | S5: Inline佐证数据 | T5: 对策合入/异常影响 | U5: 良率正贡献 （贡献加和值） | V5: 良率负影响 （影响加和值） | W5: 不良预估 现状-正贡献+负影响 | X5: Inline佐证数据 | Y5: 对策合入/异常影响 | Z5: 良率正贡献 （贡献加和值） | AA5: 良率负影响 （影响加和值） | AB5: 不良预估 现状-正贡献+负影响 | AC5: Inline佐证数据 | AD5: 对策合入/异常影响 | AE5: 良率正贡献 （贡献加和值） | AF5: 良率负影响 （影响加和值） | AG5: 不良预估 现状-正贡献+负影响 | AH5: Inline佐证数据 | AI5: 对策合入/异常影响 | AJ5: 良率正贡献 （贡献加和值） | AK5: 良率负影响 （影响加和值） | AL5: 不良预估 现状-正贡献+负影响 | AM5: Inline佐证数据 | AN5: 对策合入/异常影响 | AO5: 良率正贡献 （贡献加和值） | AP5: 良率负影响 （影响加和值） | AQ5: 不良预估 现状-正贡献+负影响 | AR5: Inline佐证数据 | AS5: 对策合入/异常影响 | AT5: 良率正贡献 （贡献加和值） | AU5: 良率负影响 （影响加和值） | AV5: 不良预估 现状-正贡献+负影响 | AW5: Inline佐证数据 | AX5: 对策合入/异常影响 | AY5: 良率正贡献 （贡献加和值） | AZ5: 良率负影响 （影响加和值） | BA5: 不良预估 现状-正贡献+负影响 | BB5: Inline佐证数据 | BC5: 对策合入/异常影响 | BD5: 良率正贡献 （贡献加和值） | BE5: 良率负影响 （影响加和值） | BF5: 不良预估 现状-正贡献+负影响 | BG5: Inline佐证数据 | BH5: 对策合入/异常影响 | BI5: 良率正贡献 （贡献加和值） | BJ5: 良率负影响 （影响加和值） | BK5: 不良预估 现状-正贡献+负影响 | BL5: Inline佐证数据 | BM5: 对策合入/异常影响 | BN5: 良率正贡献 （贡献加和值） | BO5: 良率负影响 （影响加和值） | BP5: 不良预估 现状-正贡献+负影响 | BQ5: Inline佐证数据
A6: 入库数 | B6: =_xlfn.IFNA(VLOOKUP($A6,批次辅助!$A$4:$DC$41,MATCH($A$5&B$4,批次辅助!$A$1:$DC$1,0),0),0) -> 180270 | C6: =_xlfn.IFNA(VLOOKUP($A6,批次辅助!$A$4:$DC$41,MATCH($A$5&C$4,批次辅助!$A$1:$DC$1,0),0),0) -> 161100 | D6: =_xlfn.IFNA(VLOOKUP($A6,批次辅助!$A$4:$DC$41,MATCH($A$5&D$4,批次辅助!$A$1:$DC$1,0),0),0) -> 0 | E6: =_xlfn.IFNA(VLOOKUP($A$5&E$4,'PMC数据辅助&月良率预估'!$B$2:$G$599,5,0),0) -> 1440 | J6: =_xlfn.IFNA(VLOOKUP($A$5&J$4,'PMC数据辅助&月良率预估'!$B$2:$G$599,5,0),0) -> 0 | O6: =_xlfn.IFNA(VLOOKUP($A$5&O$4,'PMC数据辅助&月良率预估'!$B$2:$G$599,5,0),0) -> 0 | T6: =_xlfn.IFNA(VLOOKUP($A$5&T$4,'PMC数据辅助&月良率预估'!$B$2:$G$599,5,0),0) -> 0 | Y6: =_xlfn.IFNA(VLOOKUP($A$5&Y$4,'PMC数据辅助&月良率预估'!$B$2:$G$599,5,0),0) -> 0 | AD6: =_xlfn.IFNA(VLOOKUP($A$5&AD$4,'PMC数据辅助&月良率预估'!$B$2:$G$599,5,0),0) -> 0 | AI6: =_xlfn.IFNA(VLOOKUP($A$5&AI$4,'PMC数据辅助&月良率预估'!$B$2:$G$599,5,0),0) -> 0 | AN6: =_xlfn.IFNA(VLOOKUP($A$5&AN$4,'PMC数据辅助&月良率预估'!$B$2:$G$599,5,0),0) -> 0 | AS6: =_xlfn.IFNA(VLOOKUP($A$5&AS$4,'PMC数据辅助&月良率预估'!$B$2:$G$599,5,0),0) -> 0 | AX6: =_xlfn.IFNA(VLOOKUP($A$5&AX$4,'PMC数据辅助&月良率预估'!$B$2:$G$599,5,0),0) -> 0 | BC6: =_xlfn.IFNA(VLOOKUP($A$5&BC$4,'PMC数据辅助&月良率预估'!$B$2:$G$599,5,0),0) -> 0 | BH6: =_xlfn.IFNA(VLOOKUP($A$5&BH$4,'PMC数据辅助&月良率预估'!$B$2:$G$599,5,0),0) -> 0 | BM6: =_xlfn.IFNA(VLOOKUP($A$5&BM$4,'PMC数据辅助&月良率预估'!$B$2:$G$599,5,0),0) -> 0
A7: 蒸镀数量 | B7: =_xlfn.IFNA(VLOOKUP($A7,批次辅助!$A$4:$DC$41,MATCH($A$5&B$4,批次辅助!$A$1:$DC$1,0),0),0) -> 180360 | C7: =_xlfn.IFNA(VLOOKUP($A7,批次辅助!$A$4:$DC$41,MATCH($A$5&C$4,批次辅助!$A$1:$DC$1,0),0),0) -> 161460 | D7: =_xlfn.IFNA(VLOOKUP($A7,批次辅助!$A$4:$DC$41,MATCH($A$5&D$4,批次辅助!$A$1:$DC$1,0),0),0) -> 0 | E7: =_xlfn.IFNA(VLOOKUP($A$5&E$4,'PMC数据辅助&月良率预估'!$B$2:$G$599,6,0),0) -> 1440 | J7: =_xlfn.IFNA(VLOOKUP($A$5&J$4,'PMC数据辅助&月良率预估'!$B$2:$G$599,6,0),0) -> 0 | O7: =_xlfn.IFNA(VLOOKUP($A$5&O$4,'PMC数据辅助&月良率预估'!$B$2:$G$599,6,0),0) -> 0 | T7: =_xlfn.IFNA(VLOOKUP($A$5&T$4,'PMC数据辅助&月良率预估'!$B$2:$G$599,6,0),0) -> 0 | Y7: =_xlfn.IFNA(VLOOKUP($A$5&Y$4,'PMC数据辅助&月良率预估'!$B$2:$G$599,6,0),0) -> 0 | AD7: =_xlfn.IFNA(VLOOKUP($A$5&AD$4,'PMC数据辅助&月良率预估'!$B$2:$G$599,6,0),0) -> 0 | AI7: =_xlfn.IFNA(VLOOKUP($A$5&AI$4,'PMC数据辅助&月良率预估'!$B$2:$G$599,6,0),0) -> 0 | AN7: =_xlfn.IFNA(VLOOKUP($A$5&AN$4,'PMC数据辅助&月良率预估'!$B$2:$G$599,6,0),0) -> 0 | AS7: =_xlfn.IFNA(VLOOKUP($A$5&AS$4,'PMC数据辅助&月良率预估'!$B$2:$G$599,6,0),0) -> 0 | AX7: =_xlfn.IFNA(VLOOKUP($A$5&AX$4,'PMC数据辅助&月良率预估'!$B$2:$G$599,6,0),0) -> 0 | BC7: =_xlfn.IFNA(VLOOKUP($A$5&BC$4,'PMC数据辅助&月良率预估'!$B$2:$G$599,6,0),0) -> 0 | BH7: =_xlfn.IFNA(VLOOKUP($A$5&BH$4,'PMC数据辅助&月良率预估'!$B$2:$G$599,6,0),0) -> 0 | BM7: =_xlfn.IFNA(VLOOKUP($A$5&BM$4,'PMC数据辅助&月良率预估'!$B$2:$G$599,6,0),0) -> 0
A8: 批次入库率 | B8: =_xlfn.IFNA(VLOOKUP($A8,批次辅助!$A$4:$DC$41,MATCH($A$5&B$4,批次辅助!$A$1:$DC$1,0),0),0) -> 1 | C8: =_xlfn.IFNA(VLOOKUP($A8,批次辅助!$A$4:$DC$41,MATCH($A$5&C$4,批次辅助!$A$1:$DC$1,0),0),0) -> 1 | D8: =_xlfn.IFNA(VLOOKUP($A8,批次辅助!$A$4:$DC$41,MATCH($A$5&D$4,批次辅助!$A$1:$DC$1,0),0),0) -> 0 | E8: =IF(E6=0,0%,E7/E6) -> 1 | J8: =IF(J6=0,0%,J7/J6) -> 0 | O8: =IF(O6=0,0%,O7/O6) -> 0 | T8: =IF(T6=0,0%,T7/T6) -> 0 | Y8: =IF(Y6=0,0%,Y7/Y6) -> 0 | AD8: =IF(AD6=0,0%,AD7/AD6) -> 0 | AI8: =IF(AI6=0,0%,AI7/AI6) -> 0 | AN8: =IF(AN6=0,0%,AN7/AN6) -> 0 | AS8: =IF(AS6=0,0%,AS7/AS6) -> 0 | AX8: =IF(AX6=0,0%,AX7/AX6) -> 0 | BC8: =IF(BC6=0,0%,BC7/BC6) -> 0 | BH8: =IF(BH6=0,0%,BH7/BH6) -> 0 | BM8: =IF(BM6=0,0%,BM7/BM6) -> 0
A9: 入库良率 | B9: =_xlfn.IFNA(VLOOKUP($A9,批次辅助!$A$4:$DC$41,MATCH($A$5&B$4,批次辅助!$A$1:$DC$1,0),0),0) -> 0.80730571 | C9: =_xlfn.IFNA(VLOOKUP($A9,批次辅助!$A$4:$DC$41,MATCH($A$5&C$4,批次辅助!$A$1:$DC$1,0),0),0) -> 0.83181254 | D9: =_xlfn.IFNA(VLOOKUP($A9,批次辅助!$A$4:$DC$41,MATCH($A$5&D$4,批次辅助!$A$1:$DC$1,0),0),0) -> 0 | H9: =H10-H19-H27-H28-H36-H37-H44-H45 -> 0.86076798 | M9: =M10-M19-M27-M28-M36-M37-M44-M45 -> 0.86076798 | R9: =R10-R19-R27-R28-R36-R37-R44-R45 -> 0.86076798 | W9: =W10-W19-W27-W28-W36-W37-W44-W45 -> 0.86076798 | AB9: =AB10-AB19-AB27-AB28-AB36-AB37-AB44-AB45 -> 0.86076798 | AG9: =AG10-AG19-AG27-AG28-AG36-AG37-AG44-AG45 -> 0.86076798 | AL9: =AL10-AL19-AL27-AL28-AL36-AL37-AL44-AL45 -> 0.86076798 | AQ9: =AQ10-AQ19-AQ27-AQ28-AQ36-AQ37-AQ44-AQ45 -> 0.86076798 | AV9: =AV10-AV19-AV27-AV28-AV36-AV37-AV44-AV45 -> 0.86076798 | BA9: =BA10-BA19-BA27-BA28-BA36-BA37-BA44-BA45 -> 0.86076798 | BF9: =BF10-BF19-BF27-BF28-BF36-BF37-BF44-BF45 -> 0.86076798 | BK9: =BK10-BK19-BK27-BK28-BK36-BK37-BK44-BK45 -> 0.86076798 | BP9: =BP10-BP19-BP27-BP28-BP36-BP37-BP44-BP45 -> 0.86076798
A10: 屏体良率 | B10: =B9+B19+B27+B28+B36+B37+B44+B45 -> 0.85705886 | C10: =C9+C19+C27+C28+C36+C37+C44+C45 -> 0.84960031 | D10: =D9+D19+D27+D28+D36+D37+D44+D45 -> 0 | H10: =(H12+H21+H30+H39)*99.94%-3 -> 0.86575575 | M10: =(M12+M21+M30+M39)*99.94%-3 -> 0.86575575 | R10: =(R12+R21+R30+R39)*99.94%-3 -> 0.86575575 | W10: =(W12+W21+W30+W39)*99.94%-3 -> 0.86575575 | AB10: =(AB12+AB21+AB30+AB39)*99.94%-3 -> 0.86575575 | AG10: =(AG12+AG21+AG30+AG39)*99.94%-3 -> 0.86575575 | AL10: =(AL12+AL21+AL30+AL39)*99.94%-3 -> 0.86575575 | AQ10: =(AQ12+AQ21+AQ30+AQ39)*99.94%-3 -> 0.86575575 | AV10: =(AV12+AV21+AV30+AV39)*99.94%-3 -> 0.86575575 | BA10: =(BA12+BA21+BA30+BA39)*99.94%-3 -> 0.86575575 | BF10: =(BF12+BF21+BF30+BF39)*99.94%-3 -> 0.86575575 | BK10: =(BK12+BK21+BK30+BK39)*99.94%-3 -> 0.86575575 | BP10: =(BP12+BP21+BP30+BP39)*99.94%-3 -> 0.86575575
A11: Array | H11: =H12*99.9% -> 0.88887436 | M11: =M12*99.9% -> 0.88887436 | R11: =R12*99.9% -> 0.88887436 | W11: =W12*99.9% -> 0.88887436 | AB11: =AB12*99.9% -> 0.88887436 | AG11: =AG12*99.9% -> 0.88887436 | AL11: =AL12*99.9% -> 0.88887436 | AQ11: =AQ12*99.9% -> 0.88887436 | AV11: =AV12*99.9% -> 0.88887436 | BA11: =BA12*99.9% -> 0.88887436 | BF11: =BF12*99.9% -> 0.88887436 | BK11: =BK12*99.9% -> 0.88887436 | BP11: =BP12*99.9% -> 0.88887436
A12: ARRAY还原入库良率 | B12: =_xlfn.IFNA(VLOOKUP($A12,批次辅助!$A$4:$DC$41,MATCH($A$5&B$4,批次辅助!$A$1:$DC$1,0),0),0) -> 0.87677928 | C12: =_xlfn.IFNA(VLOOKUP($A12,批次辅助!$A$4:$DC$41,MATCH($A$5&C$4,批次辅助!$A$1:$DC$1,0),0),0) -> 0.88873681 | D12: =_xlfn.IFNA(VLOOKUP($A12,批次辅助!$A$4:$DC$41,MATCH($A$5&D$4,批次辅助!$A$1:$DC$1,0),0),0) -> 0 | H12: =1-SUM(H13:H18) -> 0.88976412 | M12: =1-SUM(M13:M18) -> 0.88976412 | R12: =1-SUM(R13:R18) -> 0.88976412 | W12: =1-SUM(W13:W18) -> 0.88976412 | AB12: =1-SUM(AB13:AB18) -> 0.88976412 | AG12: =1-SUM(AG13:AG18) -> 0.88976412 | AL12: =1-SUM(AL13:AL18) -> 0.88976412 | AQ12: =1-SUM(AQ13:AQ18) -> 0.88976412 | AV12: =1-SUM(AV13:AV18) -> 0.88976412 | BA12: =1-SUM(BA13:BA18) -> 0.88976412 | BF12: =1-SUM(BF13:BF18) -> 0.88976412 | BK12: =1-SUM(BK13:BK18) -> 0.88976412 | BP12: =1-SUM(BP13:BP18) -> 0.88976412
A13: Array_AD | B13: =_xlfn.IFNA(VLOOKUP($A13,批次辅助!$A$4:$DC$41,MATCH($A$5&B$4,批次辅助!$A$1:$DC$1,0),0),0) -> 0.033283408 | C13: =_xlfn.IFNA(VLOOKUP($A13,批次辅助!$A$4:$DC$41,MATCH($A$5&C$4,批次辅助!$A$1:$DC$1,0),0),0) -> 0.027479826 | D13: =_xlfn.IFNA(VLOOKUP($A13,批次辅助!$A$4:$DC$41,MATCH($A$5&D$4,批次辅助!$A$1:$DC$1,0),0),0) -> 0 | H13: =C13-F13+G13 -> 0.027479826 | M13: =H13-K13+L13 -> 0.027479826 | R13: =M13-P13+Q13 -> 0.027479826 | W13: =R13-U13+V13 -> 0.027479826 | AB13: =W13-Z13+AA13 -> 0.027479826 | AG13: =AB13-AE13+AF13 -> 0.027479826 | AL13: =AG13-AJ13+AK13 -> 0.027479826 | AQ13: =AL13-AO13+AP13 -> 0.027479826 | AV13: =AQ13-AT13+AU13 -> 0.027479826 | BA13: =AV13-AY13+AZ13 -> 0.027479826 | BF13: =BA13-BD13+BE13 -> 0.027479826 | BK13: =BF13-BI13+BJ13 -> 0.027479826 | BP13: =BK13-BN13+BO13 -> 0.027479826
A14: Array_Line | B14: =_xlfn.IFNA(VLOOKUP($A14,批次辅助!$A$4:$DC$41,MATCH($A$5&B$4,批次辅助!$A$1:$DC$1,0),0),0) -> 0.037294059 | C14: =_xlfn.IFNA(VLOOKUP($A14,批次辅助!$A$4:$DC$41,MATCH($A$5&C$4,批次辅助!$A$1:$DC$1,0),0),0) -> 0.033190565 | D14: =_xlfn.IFNA(VLOOKUP($A14,批次辅助!$A$4:$DC$41,MATCH($A$5&D$4,批次辅助!$A$1:$DC$1,0),0),0) -> 0 | H14: =C14-F14+G14 -> 0.033190565 | M14: =H14-K14+L14 -> 0.033190565 | R14: =M14-P14+Q14 -> 0.033190565 | W14: =R14-U14+V14 -> 0.033190565 | AB14: =W14-Z14+AA14 -> 0.033190565 | AG14: =AB14-AE14+AF14 -> 0.033190565 | AL14: =AG14-AJ14+AK14 -> 0.033190565 | AQ14: =AL14-AO14+AP14 -> 0.033190565 | AV14: =AQ14-AT14+AU14 -> 0.033190565 | BA14: =AV14-AY14+AZ14 -> 0.033190565 | BF14: =BA14-BD14+BE14 -> 0.033190565 | BK14: =BF14-BI14+BJ14 -> 0.033190565 | BP14: =BK14-BN14+BO14 -> 0.033190565
A15: Array_Mura | B15: =_xlfn.IFNA(VLOOKUP($A15,批次辅助!$A$4:$DC$41,MATCH($A$5&B$4,批次辅助!$A$1:$DC$1,0),0),0) -> 0.0052754202 | C15: =_xlfn.IFNA(VLOOKUP($A15,批次辅助!$A$4:$DC$41,MATCH($A$5&C$4,批次辅助!$A$1:$DC$1,0),0),0) -> 0.0092302917 | D15: =_xlfn.IFNA(VLOOKUP($A15,批次辅助!$A$4:$DC$41,MATCH($A$5&D$4,批次辅助!$A$1:$DC$1,0),0),0) -> 0 | E15: 1F400 2#液刀导致IGZO偏小导致常暗黑斑Mura和S向带状Mura改善，清洁无效@1/31，目前做转向验证，预计3/18出结果 | H15: =C15-F15+G15 -> 0.0092302917 | M15: =H15-K15+L15 -> 0.0092302917 | R15: =M15-P15+Q15 -> 0.0092302917 | W15: =R15-U15+V15 -> 0.0092302917 | AB15: =W15-Z15+AA15 -> 0.0092302917 | AG15: =AB15-AE15+AF15 -> 0.0092302917 | AL15: =AG15-AJ15+AK15 -> 0.0092302917 | AQ15: =AL15-AO15+AP15 -> 0.0092302917 | AV15: =AQ15-AT15+AU15 -> 0.0092302917 | BA15: =AV15-AY15+AZ15 -> 0.0092302917 | BF15: =BA15-BD15+BE15 -> 0.0092302917 | BK15: =BF15-BI15+BJ15 -> 0.0092302917 | BP15: =BK15-BN15+BO15 -> 0.0092302917
A16: Array_Pixel | B16: =_xlfn.IFNA(VLOOKUP($A16,批次辅助!$A$4:$DC$41,MATCH($A$5&B$4,批次辅助!$A$1:$DC$1,0),0),0) -> 0.029294946 | C16: =_xlfn.IFNA(VLOOKUP($A16,批次辅助!$A$4:$DC$41,MATCH($A$5&C$4,批次辅助!$A$1:$DC$1,0),0),0) -> 0.03097455 | D16: =_xlfn.IFNA(VLOOKUP($A16,批次辅助!$A$4:$DC$41,MATCH($A$5&D$4,批次辅助!$A$1:$DC$1,0),0),0) -> 0 | H16: =C16-F16+G16 -> 0.03097455 | M16: =H16-K16+L16 -> 0.03097455 | R16: =M16-P16+Q16 -> 0.03097455 | W16: =R16-U16+V16 -> 0.03097455 | AB16: =W16-Z16+AA16 -> 0.03097455 | AG16: =AB16-AE16+AF16 -> 0.03097455 | AL16: =AG16-AJ16+AK16 -> 0.03097455 | AQ16: =AL16-AO16+AP16 -> 0.03097455 | AV16: =AQ16-AT16+AU16 -> 0.03097455 | BA16: =AV16-AY16+AZ16 -> 0.03097455 | BF16: =BA16-BD16+BE16 -> 0.03097455 | BK16: =BF16-BI16+BJ16 -> 0.03097455 | BP16: =BK16-BN16+BO16 -> 0.03097455
A17: ARRAY_RS查杀 | B17: =_xlfn.IFNA(VLOOKUP($A17,批次辅助!$A$4:$DC$41,MATCH($A$5&B$4,批次辅助!$A$1:$DC$1,0),0),0) -> 0.0073667277 | C17: =_xlfn.IFNA(VLOOKUP($A17,批次辅助!$A$4:$DC$41,MATCH($A$5&C$4,批次辅助!$A$1:$DC$1,0),0),0) -> 0.0087585351 | D17: =_xlfn.IFNA(VLOOKUP($A17,批次辅助!$A$4:$DC$41,MATCH($A$5&D$4,批次辅助!$A$1:$DC$1,0),0),0) -> 0 | H17: =C17-F17+G17 -> 0.0087585351 | M17: =H17-K17+L17 -> 0.0087585351 | R17: =M17-P17+Q17 -> 0.0087585351 | W17: =R17-U17+V17 -> 0.0087585351 | AB17: =W17-Z17+AA17 -> 0.0087585351 | AG17: =AB17-AE17+AF17 -> 0.0087585351 | AL17: =AG17-AJ17+AK17 -> 0.0087585351 | AQ17: =AL17-AO17+AP17 -> 0.0087585351 | AV17: =AQ17-AT17+AU17 -> 0.0087585351 | BA17: =AV17-AY17+AZ17 -> 0.0087585351 | BF17: =BA17-BD17+BE17 -> 0.0087585351 | BK17: =BF17-BI17+BJ17 -> 0.0087585351 | BP17: =BK17-BN17+BO17 -> 0.0087585351
A18: ARRAY其他 | B18: =_xlfn.IFNA(VLOOKUP($A18,批次辅助!$A$4:$DC$41,MATCH($A$5&B$4,批次辅助!$A$1:$DC$1,0),0),0) -> 0.00019415321 | C18: =_xlfn.IFNA(VLOOKUP($A18,批次辅助!$A$4:$DC$41,MATCH($A$5&C$4,批次辅助!$A$1:$DC$1,0),0),0) -> 0.00060211049 | D18: =_xlfn.IFNA(VLOOKUP($A18,批次辅助!$A$4:$DC$41,MATCH($A$5&D$4,批次辅助!$A$1:$DC$1,0),0),0) -> 0 | H18: =C18-F18+G18 -> 0.00060211049 | M18: =H18-K18+L18 -> 0.00060211049 | R18: =M18-P18+Q18 -> 0.00060211049 | W18: =R18-U18+V18 -> 0.00060211049 | AB18: =W18-Z18+AA18 -> 0.00060211049 | AG18: =AB18-AE18+AF18 -> 0.00060211049 | AL18: =AG18-AJ18+AK18 -> 0.00060211049 | AQ18: =AL18-AO18+AP18 -> 0.00060211049 | AV18: =AQ18-AT18+AU18 -> 0.00060211049 | BA18: =AV18-AY18+AZ18 -> 0.00060211049 | BF18: =BA18-BD18+BE18 -> 0.00060211049 | BK18: =BF18-BI18+BJ18 -> 0.00060211049 | BP18: =BK18-BN18+BO18 -> 0.00060211049
A19: 风险品（Array） | B19: =_xlfn.IFNA(VLOOKUP($A19,批次辅助!$A$4:$DC$41,MATCH($A$5&B$4,批次辅助!$A$1:$DC$1,0),0),0) -> 0.010656238 | C19: =_xlfn.IFNA(VLOOKUP($A19,批次辅助!$A$4:$DC$41,MATCH($A$5&C$4,批次辅助!$A$1:$DC$1,0),0),0) -> 0 | D19: =_xlfn.IFNA(VLOOKUP($A19,批次辅助!$A$4:$DC$41,MATCH($A$5&D$4,批次辅助!$A$1:$DC$1,0),0),0) -> 0 | H19: =C19-F19+G19 -> 0 | M19: =H19-K19+L19 -> 0 | R19: =M19-P19+Q19 -> 0 | W19: =R19-U19+V19 -> 0 | AB19: =W19-Z19+AA19 -> 0 | AG19: =AB19-AE19+AF19 -> 0 | AL19: =AG19-AJ19+AK19 -> 0 | AQ19: =AL19-AO19+AP19 -> 0 | AV19: =AQ19-AT19+AU19 -> 0 | BA19: =AV19-AY19+AZ19 -> 0 | BF19: =BA19-BD19+BE19 -> 0 | BK19: =BF19-BI19+BJ19 -> 0 | BP19: =BK19-BN19+BO19 -> 0
A20: OLED | H20: =H21*99.9% -> 0.98871483 | M20: =M21*99.9% -> 0.98871483 | R20: =R21*99.9% -> 0.98871483 | W20: =W21*99.9% -> 0.98871483 | AB20: =AB21*99.9% -> 0.98871483 | AG20: =AG21*99.9% -> 0.98871483 | AL20: =AL21*99.9% -> 0.98871483 | AQ20: =AQ21*99.9% -> 0.98871483 | AV20: =AV21*99.9% -> 0.98871483 | BA20: =BA21*99.9% -> 0.98871483 | BF20: =BF21*99.9% -> 0.98871483 | BK20: =BK21*99.9% -> 0.98871483 | BP20: =BP21*99.9% -> 0.98871483
A21: OLED还原入库良率 | B21: =_xlfn.IFNA(VLOOKUP($A21,批次辅助!$A$4:$DC$41,MATCH($A$5&B$4,批次辅助!$A$1:$DC$1,0),0),0) -> 0.97245243 | C21: =_xlfn.IFNA(VLOOKUP($A21,批次辅助!$A$4:$DC$41,MATCH($A$5&C$4,批次辅助!$A$1:$DC$1,0),0),0) -> 0.96191496 | D21: =_xlfn.IFNA(VLOOKUP($A21,批次辅助!$A$4:$DC$41,MATCH($A$5&D$4,批次辅助!$A$1:$DC$1,0),0),0) -> 0 | H21: =1-SUM(H22:H26) -> 0.98970453 | M21: =1-SUM(M22:M26) -> 0.98970453 | R21: =1-SUM(R22:R26) -> 0.98970453 | W21: =1-SUM(W22:W26) -> 0.98970453 | AB21: =1-SUM(AB22:AB26) -> 0.98970453 | AG21: =1-SUM(AG22:AG26) -> 0.98970453 | AL21: =1-SUM(AL22:AL26) -> 0.98970453 | AQ21: =1-SUM(AQ22:AQ26) -> 0.98970453 | AV21: =1-SUM(AV22:AV26) -> 0.98970453 | BA21: =1-SUM(BA22:BA26) -> 0.98970453 | BF21: =1-SUM(BF22:BF26) -> 0.98970453 | BK21: =1-SUM(BK22:BK26) -> 0.98970453 | BP21: =1-SUM(BP22:BP26) -> 0.98970453
A22: OLED_Mura | B22: =_xlfn.IFNA(VLOOKUP($A22,批次辅助!$A$4:$DC$41,MATCH($A$5&B$4,批次辅助!$A$1:$DC$1,0),0),0) -> 0.0046374882 | C22: =_xlfn.IFNA(VLOOKUP($A22,批次辅助!$A$4:$DC$41,MATCH($A$5&C$4,批次辅助!$A$1:$DC$1,0),0),0) -> 0.0050465549 | D22: =_xlfn.IFNA(VLOOKUP($A22,批次辅助!$A$4:$DC$41,MATCH($A$5&D$4,批次辅助!$A$1:$DC$1,0),0),0) -> 0 | H22: =C22-F22+G22 -> 0.0050465549 | M22: =H22-K22+L22 -> 0.0050465549 | R22: =M22-P22+Q22 -> 0.0050465549 | W22: =R22-U22+V22 -> 0.0050465549 | Y22: / | AB22: =W22-Z22+AA22 -> 0.0050465549 | AD22: / | AG22: =AB22-AE22+AF22 -> 0.0050465549 | AI22: / | AL22: =AG22-AJ22+AK22 -> 0.0050465549 | AN22: / | AQ22: =AL22-AO22+AP22 -> 0.0050465549 | AS22: / | AV22: =AQ22-AT22+AU22 -> 0.0050465549 | AX22: / | BA22: =AV22-AY22+AZ22 -> 0.0050465549 | BC22: / | BF22: =BA22-BD22+BE22 -> 0.0050465549 | BH22: / | BK22: =BF22-BI22+BJ22 -> 0.0050465549 | BM22: / | BP22: =BK22-BN22+BO22 -> 0.0050465549
A23: OLED_RS查杀 | B23: =_xlfn.IFNA(VLOOKUP($A23,批次辅助!$A$4:$DC$41,MATCH($A$5&B$4,批次辅助!$A$1:$DC$1,0),0),0) -> 0.0023187441 | C23: =_xlfn.IFNA(VLOOKUP($A23,批次辅助!$A$4:$DC$41,MATCH($A$5&C$4,批次辅助!$A$1:$DC$1,0),0),0) -> 0.0029795158 | D23: =_xlfn.IFNA(VLOOKUP($A23,批次辅助!$A$4:$DC$41,MATCH($A$5&D$4,批次辅助!$A$1:$DC$1,0),0),0) -> 0 | H23: =C23-F23+G23 -> 0.0029795158 | M23: =H23-K23+L23 -> 0.0029795158 | R23: =M23-P23+Q23 -> 0.0029795158 | W23: =R23-U23+V23 -> 0.0029795158 | Y23: / | AB23: =W23-Z23+AA23 -> 0.0029795158 | AD23: / | AG23: =AB23-AE23+AF23 -> 0.0029795158 | AI23: / | AL23: =AG23-AJ23+AK23 -> 0.0029795158 | AN23: / | AQ23: =AL23-AO23+AP23 -> 0.0029795158 | AS23: / | AV23: =AQ23-AT23+AU23 -> 0.0029795158 | AX23: / | BA23: =AV23-AY23+AZ23 -> 0.0029795158 | BC23: / | BF23: =BA23-BD23+BE23 -> 0.0029795158 | BH23: / | BK23: =BF23-BI23+BJ23 -> 0.0029795158 | BM23: / | BP23: =BK23-BN23+BO23 -> 0.0029795158
A24: OLED_色偏 | B24: =_xlfn.IFNA(VLOOKUP($A24,批次辅助!$A$4:$DC$41,MATCH($A$5&B$4,批次辅助!$A$1:$DC$1,0),0),0) -> 0 | C24: =_xlfn.IFNA(VLOOKUP($A24,批次辅助!$A$4:$DC$41,MATCH($A$5&C$4,批次辅助!$A$1:$DC$1,0),0),0) -> 0 | D24: =_xlfn.IFNA(VLOOKUP($A24,批次辅助!$A$4:$DC$41,MATCH($A$5&D$4,批次辅助!$A$1:$DC$1,0),0),0) -> 0 | H24: =C24-F24+G24 -> 0 | M24: =H24-K24+L24 -> 0 | R24: =M24-P24+Q24 -> 0 | W24: =R24-U24+V24 -> 0 | Y24: / | AB24: =W24-Z24+AA24 -> 0 | AD24: / | AG24: =AB24-AE24+AF24 -> 0 | AI24: / | AL24: =AG24-AJ24+AK24 -> 0 | AN24: / | AQ24: =AL24-AO24+AP24 -> 0 | AS24: / | AV24: =AQ24-AT24+AU24 -> 0 | AX24: / | BA24: =AV24-AY24+AZ24 -> 0 | BC24: / | BF24: =BA24-BD24+BE24 -> 0 | BH24: / | BK24: =BF24-BI24+BJ24 -> 0 | BM24: / | BP24: =BK24-BN24+BO24 -> 0
A25: OLED其他 | B25: =_xlfn.IFNA(VLOOKUP($A25,批次辅助!$A$4:$DC$41,MATCH($A$5&B$4,批次辅助!$A$1:$DC$1,0),0),0) -> 0.004631941 | C25: =_xlfn.IFNA(VLOOKUP($A25,批次辅助!$A$4:$DC$41,MATCH($A$5&C$4,批次辅助!$A$1:$DC$1,0),0),0) -> 0.016269398 | D25: =_xlfn.IFNA(VLOOKUP($A25,批次辅助!$A$4:$DC$41,MATCH($A$5&D$4,批次辅助!$A$1:$DC$1,0),0),0) -> 0 | E25: 来料翘曲改善到0.25% | F25: 0.014 | H25: =C25-F25+G25 -> 0.0022693979 | M25: =H25-K25+L25 -> 0.0022693979 | R25: =M25-P25+Q25 -> 0.0022693979 | W25: =R25-U25+V25 -> 0.0022693979 | AB25: =W25-Z25+AA25 -> 0.0022693979 | AG25: =AB25-AE25+AF25 -> 0.0022693979 | AL25: =AG25-AJ25+AK25 -> 0.0022693979 | AQ25: =AL25-AO25+AP25 -> 0.0022693979 | AV25: =AQ25-AT25+AU25 -> 0.0022693979 | BA25: =AV25-AY25+AZ25 -> 0.0022693979 | BF25: =BA25-BD25+BE25 -> 0.0022693979 | BK25: =BF25-BI25+BJ25 -> 0.0022693979 | BP25: =BK25-BN25+BO25 -> 0.0022693979
A26: OLED_开发责 | B26: =_xlfn.IFNA(VLOOKUP($A26,批次辅助!$A$4:$DC$41,MATCH($A$5&B$4,批次辅助!$A$1:$DC$1,0),0),0) -> 0 | C26: =_xlfn.IFNA(VLOOKUP($A26,批次辅助!$A$4:$DC$41,MATCH($A$5&C$4,批次辅助!$A$1:$DC$1,0),0),0) -> 0 | D26: =_xlfn.IFNA(VLOOKUP($A26,批次辅助!$A$4:$DC$41,MATCH($A$5&D$4,批次辅助!$A$1:$DC$1,0),0),0) -> 0 | H26: =C26-F26+G26 -> 0 | M26: =H26-K26+L26 -> 0 | R26: =M26-P26+Q26 -> 0 | W26: =R26-U26+V26 -> 0 | AB26: =W26-Z26+AA26 -> 0 | AG26: =AB26-AE26+AF26 -> 0 | AL26: =AG26-AJ26+AK26 -> 0 | AQ26: =AL26-AO26+AP26 -> 0 | AV26: =AQ26-AT26+AU26 -> 0 | BA26: =AV26-AY26+AZ26 -> 0 | BF26: =BA26-BD26+BE26 -> 0 | BK26: =BF26-BI26+BJ26 -> 0 | BP26: =BK26-BN26+BO26 -> 0
A27: 风险品（OLED) | B27: =_xlfn.IFNA(VLOOKUP($A27,批次辅助!$A$4:$DC$41,MATCH($A$5&B$4,批次辅助!$A$1:$DC$1,0),0),0) -> 0.015959394 | C27: =_xlfn.IFNA(VLOOKUP($A27,批次辅助!$A$4:$DC$41,MATCH($A$5&C$4,批次辅助!$A$1:$DC$1,0),0),0) -> 0.012687772 | D27: =_xlfn.IFNA(VLOOKUP($A27,批次辅助!$A$4:$DC$41,MATCH($A$5&D$4,批次辅助!$A$1:$DC$1,0),0),0) -> 0 | E27: SPC划伤风险0.5%，目前无改善方案，只能静置后检出 | F27: 0.0077 | H27: =C27-F27+G27 -> 0.0049877716 | M27: =H27-K27+L27 -> 0.0049877716 | R27: =M27-P27+Q27 -> 0.0049877716 | W27: =R27-U27+V27 -> 0.0049877716 | AB27: =W27-Z27+AA27 -> 0.0049877716 | AG27: =AB27-AE27+AF27 -> 0.0049877716 | AL27: =AG27-AJ27+AK27 -> 0.0049877716 | AQ27: =AL27-AO27+AP27 -> 0.0049877716 | AV27: =AQ27-AT27+AU27 -> 0.0049877716 | BA27: =AV27-AY27+AZ27 -> 0.0049877716 | BF27: =BA27-BD27+BE27 -> 0.0049877716 | BK27: =BF27-BI27+BJ27 -> 0.0049877716 | BP27: =BK27-BN27+BO27 -> 0.0049877716
A28: 风险品（ 未分责）
A29: TP屏体 | H29: =H30*99.96% -> 0.99040281 | M29: =M30*99.96% -> 0.99040281 | R29: =R30*99.96% -> 0.99040281 | W29: =W30*99.96% -> 0.99040281 | AB29: =AB30*99.96% -> 0.99040281 | AG29: =AG30*99.96% -> 0.99040281 | AL29: =AL30*99.96% -> 0.99040281 | AQ29: =AQ30*99.96% -> 0.99040281 | AV29: =AV30*99.96% -> 0.99040281 | BA29: =BA30*99.96% -> 0.99040281 | BF29: =BF30*99.96% -> 0.99040281 | BK29: =BK30*99.96% -> 0.99040281 | BP29: =BP30*99.96% -> 0.99040281
A30: TP还原入库良率 | B30: =_xlfn.IFNA(VLOOKUP($A30,批次辅助!$A$4:$DC$41,MATCH($A$5&B$4,批次辅助!$A$1:$DC$1,0),0),0) -> 0.98000777 | C30: =_xlfn.IFNA(VLOOKUP($A30,批次辅助!$A$4:$DC$41,MATCH($A$5&C$4,批次辅助!$A$1:$DC$1,0),0),0) -> 0.98446927 | D30: =_xlfn.IFNA(VLOOKUP($A30,批次辅助!$A$4:$DC$41,MATCH($A$5&D$4,批次辅助!$A$1:$DC$1,0),0),0) -> 0 | H30: =1-SUM(H31:H35) -> 0.99079913 | M30: =1-SUM(M31:M35) -> 0.99079913 | R30: =1-SUM(R31:R35) -> 0.99079913 | W30: =1-SUM(W31:W35) -> 0.99079913 | AB30: =1-SUM(AB31:AB35) -> 0.99079913 | AG30: =1-SUM(AG31:AG35) -> 0.99079913 | AL30: =1-SUM(AL31:AL35) -> 0.99079913 | AQ30: =1-SUM(AQ31:AQ35) -> 0.99079913 | AV30: =1-SUM(AV31:AV35) -> 0.99079913 | BA30: =1-SUM(BA31:BA35) -> 0.99079913 | BF30: =1-SUM(BF31:BF35) -> 0.99079913 | BK30: =1-SUM(BK31:BK35) -> 0.99079913 | BP30: =1-SUM(BP31:BP35) -> 0.99079913
A31: TP_NG | B31: =_xlfn.IFNA(VLOOKUP($A31,批次辅助!$A$4:$DC$41,MATCH($A$5&B$4,批次辅助!$A$1:$DC$1,0),0),0) -> 0 | C31: =_xlfn.IFNA(VLOOKUP($A31,批次辅助!$A$4:$DC$41,MATCH($A$5&C$4,批次辅助!$A$1:$DC$1,0),0),0) -> 0 | D31: =_xlfn.IFNA(VLOOKUP($A31,批次辅助!$A$4:$DC$41,MATCH($A$5&D$4,批次辅助!$A$1:$DC$1,0),0),0) -> 0 | H31: =C31-F31+G31 -> 0 | M31: =H31-K31+L31 -> 0 | O31: / | R31: =M31-P31+Q31 -> 0 | T31: / | W31: =R31-U31+V31 -> 0 | Y31: / | AB31: =W31-Z31+AA31 -> 0 | AD31: / | AG31: =AB31-AE31+AF31 -> 0 | AI31: / | AL31: =AG31-AJ31+AK31 -> 0 | AN31: / | AQ31: =AL31-AO31+AP31 -> 0 | AS31: / | AV31: =AQ31-AT31+AU31 -> 0 | AX31: / | BA31: =AV31-AY31+AZ31 -> 0 | BC31: / | BF31: =BA31-BD31+BE31 -> 0 | BH31: / | BK31: =BF31-BI31+BJ31 -> 0 | BM31: / | BP31: =BK31-BN31+BO31 -> 0
A32: TP_Short NG | B32: =_xlfn.IFNA(VLOOKUP($A32,批次辅助!$A$4:$DC$41,MATCH($A$5&B$4,批次辅助!$A$1:$DC$1,0),0),0) -> 0.0018472292 | C32: =_xlfn.IFNA(VLOOKUP($A32,批次辅助!$A$4:$DC$41,MATCH($A$5&C$4,批次辅助!$A$1:$DC$1,0),0),0) -> 0.0033954066 | D32: =_xlfn.IFNA(VLOOKUP($A32,批次辅助!$A$4:$DC$41,MATCH($A$5&D$4,批次辅助!$A$1:$DC$1,0),0),0) -> 0 | H32: =C32-F32+G32 -> 0.0033954066 | M32: =H32-K32+L32 -> 0.0033954066 | R32: =M32-P32+Q32 -> 0.0033954066 | W32: =R32-U32+V32 -> 0.0033954066 | AB32: =W32-Z32+AA32 -> 0.0033954066 | AG32: =AB32-AE32+AF32 -> 0.0033954066 | AL32: =AG32-AJ32+AK32 -> 0.0033954066 | AQ32: =AL32-AO32+AP32 -> 0.0033954066 | AV32: =AQ32-AT32+AU32 -> 0.0033954066 | BA32: =AV32-AY32+AZ32 -> 0.0033954066 | BF32: =BA32-BD32+BE32 -> 0.0033954066 | BK32: =BF32-BI32+BJ32 -> 0.0033954066 | BP32: =BK32-BN32+BO32 -> 0.0033954066
A33: TP 容值NG | B33: =_xlfn.IFNA(VLOOKUP($A33,批次辅助!$A$4:$DC$41,MATCH($A$5&B$4,批次辅助!$A$1:$DC$1,0),0),0) -> 0.0006712154 | C33: =_xlfn.IFNA(VLOOKUP($A33,批次辅助!$A$4:$DC$41,MATCH($A$5&C$4,批次辅助!$A$1:$DC$1,0),0),0) -> 0.0029919305 | D33: =_xlfn.IFNA(VLOOKUP($A33,批次辅助!$A$4:$DC$41,MATCH($A$5&D$4,批次辅助!$A$1:$DC$1,0),0),0) -> 0 | H33: =C33-F33+G33 -> 0.0029919305 | M33: =H33-K33+L33 -> 0.0029919305 | R33: =M33-P33+Q33 -> 0.0029919305 | W33: =R33-U33+V33 -> 0.0029919305 | AB33: =W33-Z33+AA33 -> 0.0029919305 | AG33: =AB33-AE33+AF33 -> 0.0029919305 | AL33: =AG33-AJ33+AK33 -> 0.0029919305 | AQ33: =AL33-AO33+AP33 -> 0.0029919305 | AV33: =AQ33-AT33+AU33 -> 0.0029919305 | BA33: =AV33-AY33+AZ33 -> 0.0029919305 | BF33: =BA33-BD33+BE33 -> 0.0029919305 | BK33: =BF33-BI33+BJ33 -> 0.0029919305 | BP33: =BK33-BN33+BO33 -> 0.0029919305
A34: TP_RS查杀 | B34: =_xlfn.IFNA(VLOOKUP($A34,批次辅助!$A$4:$DC$41,MATCH($A$5&B$4,批次辅助!$A$1:$DC$1,0),0),0) -> 0.0013257891 | C34: =_xlfn.IFNA(VLOOKUP($A34,批次辅助!$A$4:$DC$41,MATCH($A$5&C$4,批次辅助!$A$1:$DC$1,0),0),0) -> 0.0013904407 | D34: =_xlfn.IFNA(VLOOKUP($A34,批次辅助!$A$4:$DC$41,MATCH($A$5&D$4,批次辅助!$A$1:$DC$1,0),0),0) -> 0 | H34: =C34-F34+G34 -> 0.0013904407 | M34: =H34-K34+L34 -> 0.0013904407 | O34: / | R34: =M34-P34+Q34 -> 0.0013904407 | T34: / | W34: =R34-U34+V34 -> 0.0013904407 | Y34: / | AB34: =W34-Z34+AA34 -> 0.0013904407 | AD34: / | AG34: =AB34-AE34+AF34 -> 0.0013904407 | AI34: / | AL34: =AG34-AJ34+AK34 -> 0.0013904407 | AN34: / | AQ34: =AL34-AO34+AP34 -> 0.0013904407 | AS34: / | AV34: =AQ34-AT34+AU34 -> 0.0013904407 | AX34: / | BA34: =AV34-AY34+AZ34 -> 0.0013904407 | BC34: / | BF34: =BA34-BD34+BE34 -> 0.0013904407 | BH34: / | BK34: =BF34-BI34+BJ34 -> 0.0013904407 | BM34: / | BP34: =BK34-BN34+BO34 -> 0.0013904407
A35: TP其他 | B35: =_xlfn.IFNA(VLOOKUP($A35,批次辅助!$A$4:$DC$41,MATCH($A$5&B$4,批次辅助!$A$1:$DC$1,0),0),0) -> 0.0041271426 | C35: =_xlfn.IFNA(VLOOKUP($A35,批次辅助!$A$4:$DC$41,MATCH($A$5&C$4,批次辅助!$A$1:$DC$1,0),0),0) -> 0.0048230912 | D35: =_xlfn.IFNA(VLOOKUP($A35,批次辅助!$A$4:$DC$41,MATCH($A$5&D$4,批次辅助!$A$1:$DC$1,0),0),0) -> 0 | E35: 降等TP责 | F35: 0.0034 | H35: =C35-F35+G35 -> 0.0014230912 | M35: =H35-K35+L35 -> 0.0014230912 | R35: =M35-P35+Q35 -> 0.0014230912 | T35: / | W35: =R35-U35+V35 -> 0.0014230912 | Y35: / | AB35: =W35-Z35+AA35 -> 0.0014230912 | AD35: / | AG35: =AB35-AE35+AF35 -> 0.0014230912 | AI35: / | AL35: =AG35-AJ35+AK35 -> 0.0014230912 | AN35: / | AQ35: =AL35-AO35+AP35 -> 0.0014230912 | AS35: / | AV35: =AQ35-AT35+AU35 -> 0.0014230912 | AX35: / | BA35: =AV35-AY35+AZ35 -> 0.0014230912 | BC35: / | BF35: =BA35-BD35+BE35 -> 0.0014230912 | BH35: / | BK35: =BF35-BI35+BJ35 -> 0.0014230912 | BM35: / | BP35: =BK35-BN35+BO35 -> 0.0014230912
A36: 风险品（TP) | B36: =_xlfn.IFNA(VLOOKUP($A36,批次辅助!$A$4:$DC$41,MATCH($A$5&B$4,批次辅助!$A$1:$DC$1,0),0),0) -> 0.012020858 | C36: =_xlfn.IFNA(VLOOKUP($A36,批次辅助!$A$4:$DC$41,MATCH($A$5&C$4,批次辅助!$A$1:$DC$1,0),0),0) -> 0.0051 | D36: =_xlfn.IFNA(VLOOKUP($A36,批次辅助!$A$4:$DC$41,MATCH($A$5&D$4,批次辅助!$A$1:$DC$1,0),0),0) -> 0 | E36: TP 膜破影响 | F36: =C36 -> 0.0051 | H36: =C36-F36+G36 -> 0 | M36: =H36-K36+L36 -> 0 | R36: =M36-P36+Q36 -> 0 | W36: =R36-U36+V36 -> 0 | AB36: =W36-Z36+AA36 -> 0 | AG36: =AB36-AE36+AF36 -> 0 | AL36: =AG36-AJ36+AK36 -> 0 | AQ36: =AL36-AO36+AP36 -> 0 | AV36: =AQ36-AT36+AU36 -> 0 | BA36: =AV36-AY36+AZ36 -> 0 | BF36: =BA36-BD36+BE36 -> 0 | BK36: =BF36-BI36+BJ36 -> 0 | BP36: =BK36-BN36+BO36 -> 0
A37: 风险品（ 未分责）
A38: 屏体良率 | H38: =H39 -> 0.99780881 | M38: =M39 -> 0.99780881 | R38: =R39 -> 0.99780881 | W38: =W39 -> 0.99780881 | AB38: =AB39 -> 0.99780881 | AG38: =AG39 -> 0.99780881 | AL38: =AL39 -> 0.99780881 | AQ38: =AQ39 -> 0.99780881 | AV38: =AV39 -> 0.99780881 | BA38: =BA39 -> 0.99780881 | BF38: =BF39 -> 0.99780881 | BK38: =BK39 -> 0.99780881 | BP38: =BP39 -> 0.99780881
A39: 屏体还原入库良率 | B39: =_xlfn.IFNA(VLOOKUP($A39,批次辅助!$A$4:$DC$41,MATCH($A$5&B$4,批次辅助!$A$1:$DC$1,0),0),0) -> 0.98612637 | C39: =_xlfn.IFNA(VLOOKUP($A39,批次辅助!$A$4:$DC$41,MATCH($A$5&C$4,批次辅助!$A$1:$DC$1,0),0),0) -> 0.99782744 | D39: =_xlfn.IFNA(VLOOKUP($A39,批次辅助!$A$4:$DC$41,MATCH($A$5&D$4,批次辅助!$A$1:$DC$1,0),0),0) -> 0 | H39: =1-SUM(H40:H43) -> 0.99780881 | M39: =1-SUM(M40:M43) -> 0.99780881 | R39: =1-SUM(R40:R43) -> 0.99780881 | W39: =1-SUM(W40:W43) -> 0.99780881 | AB39: =1-SUM(AB40:AB43) -> 0.99780881 | AG39: =1-SUM(AG40:AG43) -> 0.99780881 | AL39: =1-SUM(AL40:AL43) -> 0.99780881 | AQ39: =1-SUM(AQ40:AQ43) -> 0.99780881 | AV39: =1-SUM(AV40:AV43) -> 0.99780881 | BA39: =1-SUM(BA40:BA43) -> 0.99780881 | BF39: =1-SUM(BF40:BF43) -> 0.99780881 | BK39: =1-SUM(BK40:BK43) -> 0.99780881 | BP39: =1-SUM(BP40:BP43) -> 0.99780881
A40: 检测技术部 | B40: =_xlfn.IFNA(VLOOKUP($A40,批次辅助!$A$4:$DC$41,MATCH($A$5&B$4,批次辅助!$A$1:$DC$1,0),0),0) -> 0.00043823154 | C40: =_xlfn.IFNA(VLOOKUP($A40,批次辅助!$A$4:$DC$41,MATCH($A$5&C$4,批次辅助!$A$1:$DC$1,0),0),0) -> 0.00039106145 | D40: =_xlfn.IFNA(VLOOKUP($A40,批次辅助!$A$4:$DC$41,MATCH($A$5&D$4,批次辅助!$A$1:$DC$1,0),0),0) -> 0 | H40: =C40-F40+G40 -> 0.00039106145 | J40: / | M40: =H40-K40+L40 -> 0.00039106145 | O40: / | R40: =M40-P40+Q40 -> 0.00039106145 | T40: / | W40: =R40-U40+V40 -> 0.00039106145 | Y40: / | AB40: =W40-Z40+AA40 -> 0.00039106145 | AD40: / | AG40: =AB40-AE40+AF40 -> 0.00039106145 | AI40: / | AL40: =AG40-AJ40+AK40 -> 0.00039106145 | AN40: / | AQ40: =AL40-AO40+AP40 -> 0.00039106145 | AS40: / | AV40: =AQ40-AT40+AU40 -> 0.00039106145 | AX40: / | BA40: =AV40-AY40+AZ40 -> 0.00039106145 | BC40: / | BF40: =BA40-BD40+BE40 -> 0.00039106145 | BH40: / | BK40: =BF40-BI40+BJ40 -> 0.00039106145 | BM40: / | BP40: =BK40-BN40+BO40 -> 0.00039106145
...

Sheet C471
B1: =VLOOKUP(A5,'PMC数据辅助&月良率预估'!$AR$3:$AS$130,2,0) -> 折叠 | C1: 0.75 | E1: A1
A2: =VLOOKUP(A5,切数!$C:$J,8,0) -> 45 | B2: 辅助列 | D2: 已生产批次 | E2: 月预估=当月各批次良率加权
A3: 预估月 | E3: =_xlfn.IFNA(VLOOKUP($A$5&E$4,'PMC数据辅助&月良率预估'!$B$2:$G$1000,2,0),"") -> M02 | J3: =_xlfn.IFNA(VLOOKUP($A$5&J$4,'PMC数据辅助&月良率预估'!$B$2:$G$1000,2,0),"") -> M03 | O3: =_xlfn.IFNA(VLOOKUP($A$5&O$4,'PMC数据辅助&月良率预估'!$B$2:$G$1000,2,0),"") -> M03 | T3: =_xlfn.IFNA(VLOOKUP($A$5&T$4,'PMC数据辅助&月良率预估'!$B$2:$G$1000,2,0),"") -> M03 | Y3: =_xlfn.IFNA(VLOOKUP($A$5&Y$4,'PMC数据辅助&月良率预估'!$B$2:$G$1000,2,0),"") -> M04 | AD3: =_xlfn.IFNA(VLOOKUP($A$5&AD$4,'PMC数据辅助&月良率预估'!$B$2:$G$1000,2,0),"") -> M04 | AI3: =_xlfn.IFNA(VLOOKUP($A$5&AI$4,'PMC数据辅助&月良率预估'!$B$2:$G$1000,2,0),"") -> M04 | AN3: =_xlfn.IFNA(VLOOKUP($A$5&AN$4,'PMC数据辅助&月良率预估'!$B$2:$G$1000,2,0),"") -> M05 | AS3: =_xlfn.IFNA(VLOOKUP($A$5&AS$4,'PMC数据辅助&月良率预估'!$B$2:$G$1000,2,0),"") -> M05 | AX3: =_xlfn.IFNA(VLOOKUP($A$5&AX$4,'PMC数据辅助&月良率预估'!$B$2:$G$1000,2,0),"") -> M06 | BC3: =_xlfn.IFNA(VLOOKUP($A$5&BC$4,'PMC数据辅助&月良率预估'!$B$2:$G$1000,2,0),"") | BH3: =_xlfn.IFNA(VLOOKUP($A$5&BH$4,'PMC数据辅助&月良率预估'!$B$2:$G$1000,2,0),"") | BM3: =_xlfn.IFNA(VLOOKUP($A$5&BM$4,'PMC数据辅助&月良率预估'!$B$2:$G$1000,2,0),"")
A4: 蒸镀批次 | B4: 26/01/18蒸镀批 | C4: 25/12/19蒸镀批 | D4: 26/01/29蒸镀批 | E4: =_xlfn.IFNA(VLOOKUP($A$5&COLUMN($A$1),'PMC数据辅助&月良率预估'!$A:$F,5,0),"") -> 01/29蒸镀批次 | J4: =_xlfn.IFNA(VLOOKUP($A$5&COLUMN($B$1),'PMC数据辅助&月良率预估'!$A:$F,5,0),"") -> 02/10蒸镀批次 | O4: =_xlfn.IFNA(VLOOKUP($A$5&COLUMN($C$1),'PMC数据辅助&月良率预估'!$A:$F,5,0),"") -> 02/20蒸镀批次 | T4: =_xlfn.IFNA(VLOOKUP($A$5&COLUMN($D$1),'PMC数据辅助&月良率预估'!$A:$F,5,0),"") -> 03/04蒸镀批次 | Y4: =_xlfn.IFNA(VLOOKUP($A$5&COLUMN($E$1),'PMC数据辅助&月良率预估'!$A:$F,5,0),"") -> 03/16蒸镀批次 | AD4: =_xlfn.IFNA(VLOOKUP($A$5&COLUMN($F$1),'PMC数据辅助&月良率预估'!$A:$F,5,0),"") -> 03/27蒸镀批次 | AI4: =_xlfn.IFNA(VLOOKUP($A$5&COLUMN($G$1),'PMC数据辅助&月良率预估'!$A:$F,5,0),"") -> 04/09蒸镀批次 | AN4: =_xlfn.IFNA(VLOOKUP($A$5&COLUMN($H$1),'PMC数据辅助&月良率预估'!$A:$F,5,0),"") -> 04/27蒸镀批次 | AS4: =_xlfn.IFNA(VLOOKUP($A$5&COLUMN($I$1),'PMC数据辅助&月良率预估'!$A:$F,5,0),"") -> 05/08蒸镀批次 | AX4: =_xlfn.IFNA(VLOOKUP($A$5&COLUMN($J$1),'PMC数据辅助&月良率预估'!$A:$F,5,0),"") -> 05/21蒸镀批次 | BC4: =_xlfn.IFNA(VLOOKUP($A$5&COLUMN($K$1),'PMC数据辅助&月良率预估'!$A:$F,5,0),"") | BH4: =_xlfn.IFNA(VLOOKUP($A$5&COLUMN($L$1),'PMC数据辅助&月良率预估'!$A:$F,5,0),"") | BM4: =_xlfn.IFNA(VLOOKUP($A$5&COLUMN($M$1),'PMC数据辅助&月良率预估'!$A:$F,5,0),"")
A5: C471 | B5: 不良率 | C5: 不良率 | E5: 对策合入/异常影响 | F5: 良率正贡献 （贡献加和值） | G5: 良率负影响 （影响加和值） | H5: 不良预估 现状-正贡献+负影响 | I5: Inline佐证数据 | J5: 对策合入/异常影响 | K5: 良率正贡献 （贡献加和值） | L5: 良率负影响 （影响加和值） | M5: 不良预估 现状-正贡献+负影响 | N5: Inline佐证数据 | O5: 对策合入/异常影响 | P5: 良率正贡献 （贡献加和值） | Q5: 良率负影响 （影响加和值） | R5: 不良预估 现状-正贡献+负影响 | S5: Inline佐证数据 | T5: 对策合入/异常影响 | U5: 良率正贡献 （贡献加和值） | V5: 良率负影响 （影响加和值） | W5: 不良预估 现状-正贡献+负影响 | X5: Inline佐证数据 | Y5: 对策合入/异常影响 | Z5: 良率正贡献 （贡献加和值） | AA5: 良率负影响 （影响加和值） | AB5: 不良预估 现状-正贡献+负影响 | AC5: Inline佐证数据 | AD5: 对策合入/异常影响 | AE5: 良率正贡献 （贡献加和值） | AF5: 良率负影响 （影响加和值） | AG5: 不良预估 现状-正贡献+负影响 | AH5: Inline佐证数据 | AI5: 对策合入/异常影响 | AJ5: 良率正贡献 （贡献加和值） | AK5: 良率负影响 （影响加和值） | AL5: 不良预估 现状-正贡献+负影响 | AM5: Inline佐证数据 | AN5: 对策合入/异常影响 | AO5: 良率正贡献 （贡献加和值） | AP5: 良率负影响 （影响加和值） | AQ5: 不良预估 现状-正贡献+负影响 | AR5: Inline佐证数据 | AS5: 对策合入/异常影响 | AT5: 良率正贡献 （贡献加和值） | AU5: 良率负影响 （影响加和值） | AV5: 不良预估 现状-正贡献+负影响 | AW5: Inline佐证数据 | AX5: 对策合入/异常影响 | AY5: 良率正贡献 （贡献加和值） | AZ5: 良率负影响 （影响加和值） | BA5: 不良预估 现状-正贡献+负影响 | BB5: Inline佐证数据 | BC5: 对策合入/异常影响 | BD5: 良率正贡献 （贡献加和值） | BE5: 良率负影响 （影响加和值） | BF5: 不良预估 现状-正贡献+负影响 | BG5: Inline佐证数据 | BH5: 对策合入/异常影响 | BI5: 良率正贡献 （贡献加和值） | BJ5: 良率负影响 （影响加和值） | BK5: 不良预估 现状-正贡献+负影响 | BL5: Inline佐证数据 | BM5: 对策合入/异常影响 | BN5: 良率正贡献 （贡献加和值） | BO5: 良率负影响 （影响加和值） | BP5: 不良预估 现状-正贡献+负影响 | BQ5: Inline佐证数据
A6: 入库数 | B6: =_xlfn.IFNA(VLOOKUP($A6,批次辅助!$A$4:$DC$41,MATCH($A$5&B$4,批次辅助!$A$1:$DC$1,0),0),0) -> 110354 | C6: =_xlfn.IFNA(VLOOKUP($A6,批次辅助!$A$4:$DC$41,MATCH($A$5&C$4,批次辅助!$A$1:$DC$1,0),0),0) -> 75195 | D6: =_xlfn.IFNA(VLOOKUP($A6,批次辅助!$A$4:$DC$41,MATCH($A$5&D$4,批次辅助!$A$1:$DC$1,0),0),0) -> 36264 | E6: =_xlfn.IFNA(VLOOKUP($A$5&E$4,'PMC数据辅助&月良率预估'!$B$2:$G$599,5,0),0) -> 958 | J6: =_xlfn.IFNA(VLOOKUP($A$5&J$4,'PMC数据辅助&月良率预估'!$B$2:$G$599,5,0),0) -> 1498 | O6: =_xlfn.IFNA(VLOOKUP($A$5&O$4,'PMC数据辅助&月良率预估'!$B$2:$G$599,5,0),0) -> 626 | T6: =_xlfn.IFNA(VLOOKUP($A$5&T$4,'PMC数据辅助&月良率预估'!$B$2:$G$599,5,0),0) -> 1667 | Y6: =_xlfn.IFNA(VLOOKUP($A$5&Y$4,'PMC数据辅助&月良率预估'!$B$2:$G$599,5,0),0) -> 1750 | AD6: =_xlfn.IFNA(VLOOKUP($A$5&AD$4,'PMC数据辅助&月良率预估'!$B$2:$G$599,5,0),0) -> 1640 | AI6: =_xlfn.IFNA(VLOOKUP($A$5&AI$4,'PMC数据辅助&月良率预估'!$B$2:$G$599,5,0),0) -> 100 | AN6: =_xlfn.IFNA(VLOOKUP($A$5&AN$4,'PMC数据辅助&月良率预估'!$B$2:$G$599,5,0),0) -> 1680 | AS6: =_xlfn.IFNA(VLOOKUP($A$5&AS$4,'PMC数据辅助&月良率预估'!$B$2:$G$599,5,0),0) -> 1680 | AX6: =_xlfn.IFNA(VLOOKUP($A$5&AX$4,'PMC数据辅助&月良率预估'!$B$2:$G$599,5,0),0) -> 1680 | BC6: =_xlfn.IFNA(VLOOKUP($A$5&BC$4,'PMC数据辅助&月良率预估'!$B$2:$G$599,5,0),0) -> 0 | BH6: =_xlfn.IFNA(VLOOKUP($A$5&BH$4,'PMC数据辅助&月良率预估'!$B$2:$G$599,5,0),0) -> 0 | BM6: =_xlfn.IFNA(VLOOKUP($A$5&BM$4,'PMC数据辅助&月良率预估'!$B$2:$G$599,5,0),0) -> 0
A7: 蒸镀数量 | B7: =_xlfn.IFNA(VLOOKUP($A7,批次辅助!$A$4:$DC$41,MATCH($A$5&B$4,批次辅助!$A$1:$DC$1,0),0),0) -> 114210 | C7: =_xlfn.IFNA(VLOOKUP($A7,批次辅助!$A$4:$DC$41,MATCH($A$5&C$4,批次辅助!$A$1:$DC$1,0),0),0) -> 75330 | D7: =_xlfn.IFNA(VLOOKUP($A7,批次辅助!$A$4:$DC$41,MATCH($A$5&D$4,批次辅助!$A$1:$DC$1,0),0),0) -> 43110 | E7: =_xlfn.IFNA(VLOOKUP($A$5&E$4,'PMC数据辅助&月良率预估'!$B$2:$G$599,6,0),0) -> 958 | J7: =_xlfn.IFNA(VLOOKUP($A$5&J$4,'PMC数据辅助&月良率预估'!$B$2:$G$599,6,0),0) -> 1498 | O7: =_xlfn.IFNA(VLOOKUP($A$5&O$4,'PMC数据辅助&月良率预估'!$B$2:$G$599,6,0),0) -> 626 | T7: =_xlfn.IFNA(VLOOKUP($A$5&T$4,'PMC数据辅助&月良率预估'!$B$2:$G$599,6,0),0) -> 1667 | Y7: =_xlfn.IFNA(VLOOKUP($A$5&Y$4,'PMC数据辅助&月良率预估'!$B$2:$G$599,6,0),0) -> 1750 | AD7: =_xlfn.IFNA(VLOOKUP($A$5&AD$4,'PMC数据辅助&月良率预估'!$B$2:$G$599,6,0),0) -> 1640 | AI7: =_xlfn.IFNA(VLOOKUP($A$5&AI$4,'PMC数据辅助&月良率预估'!$B$2:$G$599,6,0),0) -> 100 | AN7: =_xlfn.IFNA(VLOOKUP($A$5&AN$4,'PMC数据辅助&月良率预估'!$B$2:$G$599,6,0),0) -> 1680 | AS7: =_xlfn.IFNA(VLOOKUP($A$5&AS$4,'PMC数据辅助&月良率预估'!$B$2:$G$599,6,0),0) -> 1680 | AX7: =_xlfn.IFNA(VLOOKUP($A$5&AX$4,'PMC数据辅助&月良率预估'!$B$2:$G$599,6,0),0) -> 1680 | BC7: =_xlfn.IFNA(VLOOKUP($A$5&BC$4,'PMC数据辅助&月良率预估'!$B$2:$G$599,6,0),0) -> 0 | BH7: =_xlfn.IFNA(VLOOKUP($A$5&BH$4,'PMC数据辅助&月良率预估'!$B$2:$G$599,6,0),0) -> 0 | BM7: =_xlfn.IFNA(VLOOKUP($A$5&BM$4,'PMC数据辅助&月良率预估'!$B$2:$G$599,6,0),0) -> 0
A8: 批次入库率 | B8: =_xlfn.IFNA(VLOOKUP($A8,批次辅助!$A$4:$DC$41,MATCH($A$5&B$4,批次辅助!$A$1:$DC$1,0),0),0) -> 0.96702565 | C8: =_xlfn.IFNA(VLOOKUP($A8,批次辅助!$A$4:$DC$41,MATCH($A$5&C$4,批次辅助!$A$1:$DC$1,0),0),0) -> 1 | D8: =_xlfn.IFNA(VLOOKUP($A8,批次辅助!$A$4:$DC$41,MATCH($A$5&D$4,批次辅助!$A$1:$DC$1,0),0),0) -> 0.84641614 | E8: =IF(E6=0,0%,E7/E6) -> 1 | J8: =IF(J6=0,0%,J7/J6) -> 1 | O8: =IF(O6=0,0%,O7/O6) -> 1 | T8: =IF(T6=0,0%,T7/T6) -> 1 | Y8: =IF(Y6=0,0%,Y7/Y6) -> 1 | AD8: =IF(AD6=0,0%,AD7/AD6) -> 1 | AI8: =IF(AI6=0,0%,AI7/AI6) -> 1 | AN8: =IF(AN6=0,0%,AN7/AN6) -> 1 | AS8: =IF(AS6=0,0%,AS7/AS6) -> 1 | AX8: =IF(AX6=0,0%,AX7/AX6) -> 1 | BC8: =IF(BC6=0,0%,BC7/BC6) -> 0 | BH8: =IF(BH6=0,0%,BH7/BH6) -> 0 | BM8: =IF(BM6=0,0%,BM7/BM6) -> 0
A9: 入库良率 | B9: =_xlfn.IFNA(VLOOKUP($A9,批次辅助!$A$4:$DC$41,MATCH($A$5&B$4,批次辅助!$A$1:$DC$1,0),0),0) -> 0.82200917 | C9: =_xlfn.IFNA(VLOOKUP($A9,批次辅助!$A$4:$DC$41,MATCH($A$5&C$4,批次辅助!$A$1:$DC$1,0),0),0) -> 0.74483676 | D9: =_xlfn.IFNA(VLOOKUP($A9,批次辅助!$A$4:$DC$41,MATCH($A$5&D$4,批次辅助!$A$1:$DC$1,0),0),0) -> 0.79668542 | H9: =H10-H19-H27-H28-H36-H37-H44-H45 -> 0.78050838 | M9: =M10-M19-M27-M28-M36-M37-M44-M45 -> 0.83067826 | R9: =R10-R19-R27-R28-R36-R37-R44-R45 -> 0.79872938 | W9: =W10-W19-W27-W28-W36-W37-W44-W45 -> 0.81868066 | AB9: =AB10-AB19-AB27-AB28-AB36-AB37-AB44-AB45 -> 0.82568126 | AG9: =AG10-AG19-AG27-AG28-AG36-AG37-AG44-AG45 -> 0.82568126 | AL9: =AL10-AL19-AL27-AL28-AL36-AL37-AL44-AL45 -> 0.82568126 | AQ9: =AQ10-AQ19-AQ27-AQ28-AQ36-AQ37-AQ44-AQ45 -> 0.82568126 | AV9: =AV10-AV19-AV27-AV28-AV36-AV37-AV44-AV45 -> 0.83067826 | BA9: =BA10-BA19-BA27-BA28-BA36-BA37-BA44-BA45 -> 0.83067826 | BF9: =BF10-BF19-BF27-BF28-BF36-BF37-BF44-BF45 -> 0.83067826 | BK9: =BK10-BK19-BK27-BK28-BK36-BK37-BK44-BK45 -> 0.83067826 | BP9: =BP10-BP19-BP27-BP28-BP36-BP37-BP44-BP45 -> 0.83067826
A10: 屏体良率 | B10: =B9+B19+B27+B28+B36+B37+B44+B45 -> 0.82200917 | C10: =C9+C19+C27+C28+C36+C37+C44+C45 -> 0.80583676 | D10: =D9+D19+D27+D28+D36+D37+D44+D45 -> 0.79668542 | H10: =(H12+H21+H30+H39)*99.94%-3 -> 0.78050838 | M10: =(M12+M21+M30+M39)*99.94%-3 -> 0.83067826 | R10: =(R12+R21+R30+R39)*99.94%-3 -> 0.83067826 | W10: =(W12+W21+W30+W39)*99.94%-3 -> 0.83067826 | AB10: =(AB12+AB21+AB30+AB39)*99.94%-3 -> 0.82568126 | AG10: =(AG12+AG21+AG30+AG39)*99.94%-3 -> 0.82568126 | AL10: =(AL12+AL21+AL30+AL39)*99.94%-3 -> 0.82568126 | AQ10: =(AQ12+AQ21+AQ30+AQ39)*99.94%-3 -> 0.82568126 | AV10: =(AV12+AV21+AV30+AV39)*99.94%-3 -> 0.83067826 | BA10: =(BA12+BA21+BA30+BA39)*99.94%-3 -> 0.83067826 | BF10: =(BF12+BF21+BF30+BF39)*99.94%-3 -> 0.83067826 | BK10: =(BK12+BK21+BK30+BK39)*99.94%-3 -> 0.83067826 | BP10: =(BP12+BP21+BP30+BP39)*99.94%-3 -> 0.83067826
A11: Array | H11: =H12*99.9% -> 0.88161322 | M11: =M12*99.9% -> 0.88161322 | R11: =R12*99.9% -> 0.88161322 | W11: =W12*99.9% -> 0.88161322 | AB11: =AB12*99.9% -> 0.88161322 | AG11: =AG12*99.9% -> 0.88161322 | AL11: =AL12*99.9% -> 0.88161322 | AQ11: =AQ12*99.9% -> 0.88161322 | AV11: =AV12*99.9% -> 0.88161322 | BA11: =BA12*99.9% -> 0.88161322 | BF11: =BF12*99.9% -> 0.88161322 | BK11: =BK12*99.9% -> 0.88161322 | BP11: =BP12*99.9% -> 0.88161322
A12: ARRAY还原入库良率 | B12: =_xlfn.IFNA(VLOOKUP($A12,批次辅助!$A$4:$DC$41,MATCH($A$5&B$4,批次辅助!$A$1:$DC$1,0),0),0) -> 0.86907588 | C12: =_xlfn.IFNA(VLOOKUP($A12,批次辅助!$A$4:$DC$41,MATCH($A$5&C$4,批次辅助!$A$1:$DC$1,0),0),0) -> 0.83081322 | D12: =_xlfn.IFNA(VLOOKUP($A12,批次辅助!$A$4:$DC$41,MATCH($A$5&D$4,批次辅助!$A$1:$DC$1,0),0),0) -> 0.89328259 | H12: =1-SUM(H13:H18) -> 0.88249571 | M12: =1-SUM(M13:M18) -> 0.88249571 | R12: =1-SUM(R13:R18) -> 0.88249571 | W12: =1-SUM(W13:W18) -> 0.88249571 | AB12: =1-SUM(AB13:AB18) -> 0.88249571 | AG12: =1-SUM(AG13:AG18) -> 0.88249571 | AL12: =1-SUM(AL13:AL18) -> 0.88249571 | AQ12: =1-SUM(AQ13:AQ18) -> 0.88249571 | AV12: =1-SUM(AV13:AV18) -> 0.88249571 | BA12: =1-SUM(BA13:BA18) -> 0.88249571 | BF12: =1-SUM(BF13:BF18) -> 0.88249571 | BK12: =1-SUM(BK13:BK18) -> 0.88249571 | BP12: =1-SUM(BP13:BP18) -> 0.88249571
A13: Array_AD | B13: =_xlfn.IFNA(VLOOKUP($A13,批次辅助!$A$4:$DC$41,MATCH($A$5&B$4,批次辅助!$A$1:$DC$1,0),0),0) -> 0.037986842 | C13: =_xlfn.IFNA(VLOOKUP($A13,批次辅助!$A$4:$DC$41,MATCH($A$5&C$4,批次辅助!$A$1:$DC$1,0),0),0) -> 0.031185584 | D13: =_xlfn.IFNA(VLOOKUP($A13,批次辅助!$A$4:$DC$41,MATCH($A$5&D$4,批次辅助!$A$1:$DC$1,0),0),0) -> 0.037199426 | E13: ②12/19批次受2E行膜位聚集~0.3%，Array不可见，Oled 21320可见 | G13: 0.003 | H13: =C13-F13+G13 -> 0.034185584 | M13: =H13-K13+L13 -> 0.034185584 | R13: =M13-P13+Q13 -> 0.034185584 | W13: =R13-U13+V13 -> 0.034185584 | AB13: =W13-Z13+AA13 -> 0.034185584 | AG13: =AB13-AE13+AF13 -> 0.034185584 | AL13: =AG13-AJ13+AK13 -> 0.034185584 | AQ13: =AL13-AO13+AP13 -> 0.034185584 | AV13: =AQ13-AT13+AU13 -> 0.034185584 | BA13: =AV13-AY13+AZ13 -> 0.034185584 | BF13: =BA13-BD13+BE13 -> 0.034185584 | BK13: =BF13-BI13+BJ13 -> 0.034185584 | BP13: =BK13-BN13+BO13 -> 0.034185584
A14: Array_Line | B14: =_xlfn.IFNA(VLOOKUP($A14,批次辅助!$A$4:$DC$41,MATCH($A$5&B$4,批次辅助!$A$1:$DC$1,0),0),0) -> 0.027031191 | C14: =_xlfn.IFNA(VLOOKUP($A14,批次辅助!$A$4:$DC$41,MATCH($A$5&C$4,批次辅助!$A$1:$DC$1,0),0),0) -> 0.034098012 | D14: =_xlfn.IFNA(VLOOKUP($A14,批次辅助!$A$4:$DC$41,MATCH($A$5&D$4,批次辅助!$A$1:$DC$1,0),0),0) -> 0.028182219 | E14: ①17900 DE15去化，目前可Run 19900/1D900/1W900，17900暂禁Run@10/26，Wip较多时，17900开启单LLU过货 | F14: 0.003 | H14: =C14-F14+G14 -> 0.031098012 | M14: =H14-K14+L14 -> 0.031098012 | R14: =M14-P14+Q14 -> 0.031098012 | W14: =R14-U14+V14 -> 0.031098012 | AB14: =W14-Z14+AA14 -> 0.031098012 | AG14: =AB14-AE14+AF14 -> 0.031098012 | AL14: =AG14-AJ14+AK14 -> 0.031098012 | AQ14: =AL14-AO14+AP14 -> 0.031098012 | AV14: =AQ14-AT14+AU14 -> 0.031098012 | BA14: =AV14-AY14+AZ14 -> 0.031098012 | BF14: =BA14-BD14+BE14 -> 0.031098012 | BK14: =BF14-BI14+BJ14 -> 0.031098012 | BP14: =BK14-BN14+BO14 -> 0.031098012
A15: Array_Mura | B15: =_xlfn.IFNA(VLOOKUP($A15,批次辅助!$A$4:$DC$41,MATCH($A$5&B$4,批次辅助!$A$1:$DC$1,0),0),0) -> 0.03040216 | C15: =_xlfn.IFNA(VLOOKUP($A15,批次辅助!$A$4:$DC$41,MATCH($A$5&C$4,批次辅助!$A$1:$DC$1,0),0),0) -> 0.025640003 | D15: =_xlfn.IFNA(VLOOKUP($A15,批次辅助!$A$4:$DC$41,MATCH($A$5&D$4,批次辅助!$A$1:$DC$1,0),0),0) -> 0.012657181 | E15: 常亮白斑0.25%，Y已更换O-ring 12/5, 常暗黑斑0.75%，S向带状Mura 0.11%：E列，1F400 2#禁Run 12/30，做转项验证中，预计3/18出结果 | F15: 0.013 | H15: =C15-F15+G15 -> 0.012640003 | M15: =H15-K15+L15 -> 0.012640003 | R15: =M15-P15+Q15 -> 0.012640003 | W15: =R15-U15+V15 -> 0.012640003 | AB15: =W15-Z15+AA15 -> 0.012640003 | AG15: =AB15-AE15+AF15 -> 0.012640003 | AL15: =AG15-AJ15+AK15 -> 0.012640003 | AQ15: =AL15-AO15+AP15 -> 0.012640003 | AV15: =AQ15-AT15+AU15 -> 0.012640003 | BA15: =AV15-AY15+AZ15 -> 0.012640003 | BF15: =BA15-BD15+BE15 -> 0.012640003 | BK15: =BF15-BI15+BJ15 -> 0.012640003 | BP15: =BK15-BN15+BO15 -> 0.012640003
A16: Array_Pixel | B16: =_xlfn.IFNA(VLOOKUP($A16,批次辅助!$A$4:$DC$41,MATCH($A$5&B$4,批次辅助!$A$1:$DC$1,0),0),0) -> 0.026324374 | C16: =_xlfn.IFNA(VLOOKUP($A16,批次辅助!$A$4:$DC$41,MATCH($A$5&C$4,批次辅助!$A$1:$DC$1,0),0),0) -> 0.038991954 | D16: =_xlfn.IFNA(VLOOKUP($A16,批次辅助!$A$4:$DC$41,MATCH($A$5&D$4,批次辅助!$A$1:$DC$1,0),0),0) -> 0.020929848 | E16: 大面积亮点：返工Reaging | F16: 0.007 | H16: =C16-F16+G16 -> 0.031991954 | M16: =H16-K16+L16 -> 0.031991954 | R16: =M16-P16+Q16 -> 0.031991954 | W16: =R16-U16+V16 -> 0.031991954 | AB16: =W16-Z16+AA16 -> 0.031991954 | AG16: =AB16-AE16+AF16 -> 0.031991954 | AL16: =AG16-AJ16+AK16 -> 0.031991954 | AQ16: =AL16-AO16+AP16 -> 0.031991954 | AV16: =AQ16-AT16+AU16 -> 0.031991954 | BA16: =AV16-AY16+AZ16 -> 0.031991954 | BF16: =BA16-BD16+BE16 -> 0.031991954 | BK16: =BF16-BI16+BJ16 -> 0.031991954 | BP16: =BK16-BN16+BO16 -> 0.031991954
A17: ARRAY_RS查杀 | B17: =_xlfn.IFNA(VLOOKUP($A17,批次辅助!$A$4:$DC$41,MATCH($A$5&B$4,批次辅助!$A$1:$DC$1,0),0),0) -> 0.0088352031 | C17: =_xlfn.IFNA(VLOOKUP($A17,批次辅助!$A$4:$DC$41,MATCH($A$5&C$4,批次辅助!$A$1:$DC$1,0),0),0) -> 0.0067823658 | D17: =_xlfn.IFNA(VLOOKUP($A17,批次辅助!$A$4:$DC$41,MATCH($A$5&D$4,批次辅助!$A$1:$DC$1,0),0),0) -> 0.0079141849 | H17: =C17-F17+G17 -> 0.0067823658 | M17: =H17-K17+L17 -> 0.0067823658 | R17: =M17-P17+Q17 -> 0.0067823658 | W17: =R17-U17+V17 -> 0.0067823658 | AB17: =W17-Z17+AA17 -> 0.0067823658 | AG17: =AB17-AE17+AF17 -> 0.0067823658 | AL17: =AG17-AJ17+AK17 -> 0.0067823658 | AQ17: =AL17-AO17+AP17 -> 0.0067823658 | AV17: =AQ17-AT17+AU17 -> 0.0067823658 | BA17: =AV17-AY17+AZ17 -> 0.0067823658 | BF17: =BA17-BD17+BE17 -> 0.0067823658 | BK17: =BF17-BI17+BJ17 -> 0.0067823658 | BP17: =BK17-BN17+BO17 -> 0.0067823658
A18: ARRAY其他 | B18: =_xlfn.IFNA(VLOOKUP($A18,批次辅助!$A$4:$DC$41,MATCH($A$5&B$4,批次辅助!$A$1:$DC$1,0),0),0) -> 0.00050745782 | C18: =_xlfn.IFNA(VLOOKUP($A18,批次辅助!$A$4:$DC$41,MATCH($A$5&C$4,批次辅助!$A$1:$DC$1,0),0),0) -> 0.0078063701 | D18: =_xlfn.IFNA(VLOOKUP($A18,批次辅助!$A$4:$DC$41,MATCH($A$5&D$4,批次辅助!$A$1:$DC$1,0),0),0) -> 8.2726671e-05 | E18: Array其他改善 | F18: 0.007 | H18: =C18-F18+G18 -> 0.0008063701 | M18: =H18-K18+L18 -> 0.0008063701 | R18: =M18-P18+Q18 -> 0.0008063701 | W18: =R18-U18+V18 -> 0.0008063701 | AB18: =W18-Z18+AA18 -> 0.0008063701 | AG18: =AB18-AE18+AF18 -> 0.0008063701 | AL18: =AG18-AJ18+AK18 -> 0.0008063701 | AQ18: =AL18-AO18+AP18 -> 0.0008063701 | AV18: =AQ18-AT18+AU18 -> 0.0008063701 | BA18: =AV18-AY18+AZ18 -> 0.0008063701 | BF18: =BA18-BD18+BE18 -> 0.0008063701 | BK18: =BF18-BI18+BJ18 -> 0.0008063701 | BP18: =BK18-BN18+BO18 -> 0.0008063701
A19: 风险品（Array） | B19: =_xlfn.IFNA(VLOOKUP($A19,批次辅助!$A$4:$DC$41,MATCH($A$5&B$4,批次辅助!$A$1:$DC$1,0),0),0) -> 0 | C19: =_xlfn.IFNA(VLOOKUP($A19,批次辅助!$A$4:$DC$41,MATCH($A$5&C$4,批次辅助!$A$1:$DC$1,0),0),0) -> 0 | D19: =_xlfn.IFNA(VLOOKUP($A19,批次辅助!$A$4:$DC$41,MATCH($A$5&D$4,批次辅助!$A$1:$DC$1,0),0),0) -> 0 | E19: Nozzle堵塞导BPDL偏薄 299sheet，单管，1/25已改善 | H19: =C19-F19+G19 -> 0 | M19: =H19-K19+L19 -> 0 | R19: =M19-P19+Q19 -> 0 | W19: =R19-U19+V19 -> 0 | AB19: =W19-Z19+AA19 -> 0 | AG19: =AB19-AE19+AF19 -> 0 | AL19: =AG19-AJ19+AK19 -> 0 | AQ19: =AL19-AO19+AP19 -> 0 | AV19: =AQ19-AT19+AU19 -> 0 | BA19: =AV19-AY19+AZ19 -> 0 | BF19: =BA19-BD19+BE19 -> 0 | BK19: =BF19-BI19+BJ19 -> 0 | BP19: =BK19-BN19+BO19 -> 0
A20: OLED | H20: =H21*99.9% -> 0.90875521 | M20: =M21*99.9% -> 0.95680711 | R20: =R21*99.9% -> 0.95680711 | W20: =W21*99.9% -> 0.95680711 | AB20: =AB21*99.9% -> 0.95181211 | AG20: =AG21*99.9% -> 0.95181211 | AL20: =AL21*99.9% -> 0.95181211 | AQ20: =AQ21*99.9% -> 0.95181211 | AV20: =AV21*99.9% -> 0.95680711 | BA20: =BA21*99.9% -> 0.95680711 | BF20: =BF21*99.9% -> 0.95680711 | BK20: =BK21*99.9% -> 0.95680711 | BP20: =BP21*99.9% -> 0.95680711
A21: OLED还原入库良率 | B21: =_xlfn.IFNA(VLOOKUP($A21,批次辅助!$A$4:$DC$41,MATCH($A$5&B$4,批次辅助!$A$1:$DC$1,0),0),0) -> 0.9606539 | C21: =_xlfn.IFNA(VLOOKUP($A21,批次辅助!$A$4:$DC$41,MATCH($A$5&C$4,批次辅助!$A$1:$DC$1,0),0),0) -> 0.92370503 | D21: =_xlfn.IFNA(VLOOKUP($A21,批次辅助!$A$4:$DC$41,MATCH($A$5&D$4,批次辅助!$A$1:$DC$1,0),0),0) -> 0.91208912 | H21: =1-SUM(H22:H26) -> 0.90966487 | M21: =1-SUM(M22:M26) -> 0.95776487 | R21: =1-SUM(R22:R26) -> 0.95776487 | W21: =1-SUM(W22:W26) -> 0.95776487 | AB21: =1-SUM(AB22:AB26) -> 0.95276487 | AG21: =1-SUM(AG22:AG26) -> 0.95276487 | AL21: =1-SUM(AL22:AL26) -> 0.95276487 | AQ21: =1-SUM(AQ22:AQ26) -> 0.95276487 | AV21: =1-SUM(AV22:AV26) -> 0.95776487 | BA21: =1-SUM(BA22:BA26) -> 0.95776487 | BF21: =1-SUM(BF22:BF26) -> 0.95776487 | BK21: =1-SUM(BK22:BK26) -> 0.95776487 | BP21: =1-SUM(BP22:BP26) -> 0.95776487
A22: OLED_Mura | B22: =_xlfn.IFNA(VLOOKUP($A22,批次辅助!$A$4:$DC$41,MATCH($A$5&B$4,批次辅助!$A$1:$DC$1,0),0),0) -> 0.0022020045 | C22: =_xlfn.IFNA(VLOOKUP($A22,批次辅助!$A$4:$DC$41,MATCH($A$5&C$4,批次辅助!$A$1:$DC$1,0),0),0) -> 0.0018352284 | D22: =_xlfn.IFNA(VLOOKUP($A22,批次辅助!$A$4:$DC$41,MATCH($A$5&D$4,批次辅助!$A$1:$DC$1,0),0),0) -> 0.0017372601 | E22: 过程中Particle影响 | H22: =C22-F22+G22 -> 0.0018352284 | M22: =H22-K22+L22 -> 0.0018352284 | R22: =M22-P22+Q22 -> 0.0018352284 | W22: =R22-U22+V22 -> 0.0018352284 | Y22: C471 扩线2套Mask 新张网影响 | AA22: 0.005 | AB22: =W22-Z22+AA22 -> 0.0068352284 | AG22: =AB22-AE22+AF22 -> 0.0068352284 | AI22: / | AL22: =AG22-AJ22+AK22 -> 0.0068352284 | AQ22: =AL22-AO22+AP22 -> 0.0068352284 | AS22: C471 扩线2套Mask 新张网改善 | AT22: 0.005 | AV22: =AQ22-AT22+AU22 -> 0.0018352284 | AX22: / | BA22: =AV22-AY22+AZ22 -> 0.0018352284 | BC22: / | BF22: =BA22-BD22+BE22 -> 0.0018352284 | BH22: / | BK22: =BF22-BI22+BJ22 -> 0.0018352284 | BM22: / | BP22: =BK22-BN22+BO22 -> 0.0018352284
A23: OLED_RS查杀 | B23: =_xlfn.IFNA(VLOOKUP($A23,批次辅助!$A$4:$DC$41,MATCH($A$5&B$4,批次辅助!$A$1:$DC$1,0),0),0) -> 0.0034253403 | C23: =_xlfn.IFNA(VLOOKUP($A23,批次辅助!$A$4:$DC$41,MATCH($A$5&C$4,批次辅助!$A$1:$DC$1,0),0),0) -> 0.0050668263 | D23: =_xlfn.IFNA(VLOOKUP($A23,批次辅助!$A$4:$DC$41,MATCH($A$5&D$4,批次辅助!$A$1:$DC$1,0),0),0) -> 0.0035848224 | E23: / | H23: =C23-F23+G23 -> 0.0050668263 | M23: =H23-K23+L23 -> 0.0050668263 | R23: =M23-P23+Q23 -> 0.0050668263 | W23: =R23-U23+V23 -> 0.0050668263 | Y23: / | AB23: =W23-Z23+AA23 -> 0.0050668263 | AD23: / | AG23: =AB23-AE23+AF23 -> 0.0050668263 | AI23: / | AL23: =AG23-AJ23+AK23 -> 0.0050668263 | AN23: / | AQ23: =AL23-AO23+AP23 -> 0.0050668263 | AS23: / | AV23: =AQ23-AT23+AU23 -> 0.0050668263 | AX23: / | BA23: =AV23-AY23+AZ23 -> 0.0050668263 | BC23: / | BF23: =BA23-BD23+BE23 -> 0.0050668263 | BH23: / | BK23: =BF23-BI23+BJ23 -> 0.0050668263 | BM23: / | BP23: =BK23-BN23+BO23 -> 0.0050668263
A24: OLED_色偏 | B24: =_xlfn.IFNA(VLOOKUP($A24,批次辅助!$A$4:$DC$41,MATCH($A$5&B$4,批次辅助!$A$1:$DC$1,0),0),0) -> 0.028961343 | C24: =_xlfn.IFNA(VLOOKUP($A24,批次辅助!$A$4:$DC$41,MATCH($A$5&C$4,批次辅助!$A$1:$DC$1,0),0),0) -> 0.024908571 | D24: =_xlfn.IFNA(VLOOKUP($A24,批次辅助!$A$4:$DC$41,MATCH($A$5&D$4,批次辅助!$A$1:$DC$1,0),0),0) -> 0.074288551 | E24: JNCDN持续恶化5% | G24: 0.05 | H24: =C24-F24+G24 -> 0.074908571 | J24: 色轨迹调整，预计改善到3% | K24: 0.045 | M24: =H24-K24+L24 -> 0.029908571 | R24: =M24-P24+Q24 -> 0.029908571 | W24: =R24-U24+V24 -> 0.029908571 | AB24: =W24-Z24+AA24 -> 0.029908571 | AD24: / | AG24: =AB24-AE24+AF24 -> 0.029908571 | AI24: / | AL24: =AG24-AJ24+AK24 -> 0.029908571 | AN24: / | AQ24: =AL24-AO24+AP24 -> 0.029908571 | AS24: / | AV24: =AQ24-AT24+AU24 -> 0.029908571 | AX24: / | BA24: =AV24-AY24+AZ24 -> 0.029908571 | BC24: / | BF24: =BA24-BD24+BE24 -> 0.029908571 | BH24: / | BK24: =BF24-BI24+BJ24 -> 0.029908571 | BM24: / | BP24: =BK24-BN24+BO24 -> 0.029908571
A25: OLED其他 | B25: =_xlfn.IFNA(VLOOKUP($A25,批次辅助!$A$4:$DC$41,MATCH($A$5&B$4,批次辅助!$A$1:$DC$1,0),0),0) -> 0.004757417 | C25: =_xlfn.IFNA(VLOOKUP($A25,批次辅助!$A$4:$DC$41,MATCH($A$5&C$4,批次辅助!$A$1:$DC$1,0),0),0) -> 0.008524503 | D25: =_xlfn.IFNA(VLOOKUP($A25,批次辅助!$A$4:$DC$41,MATCH($A$5&D$4,批次辅助!$A$1:$DC$1,0),0),0) -> 0.0083002427 | E25: OLED翘曲0.06%→0.29%：①当前Lami优先LLO2#作业；LLO1#临时禁用；②下批次LLO能量 DOE验证优化； 屏体破裂0.17%→0.24%： LLO #1，DLA #2禁run ②优化设备参数 @3/1 | H25: =C25-F25+G25 -> 0.008524503 | J25: OLED翘曲和屏体破裂 | K25: 0.0031 | M25: =H25-K25+L25 -> 0.005424503 | R25: =M25-P25+Q25 -> 0.005424503 | W25: =R25-U25+V25 -> 0.005424503 | AB25: =W25-Z25+AA25 -> 0.005424503 | AG25: =AB25-AE25+AF25 -> 0.005424503 | AL25: =AG25-AJ25+AK25 -> 0.005424503 | AQ25: =AL25-AO25+AP25 -> 0.005424503 | AV25: =AQ25-AT25+AU25 -> 0.005424503 | BA25: =AV25-AY25+AZ25 -> 0.005424503 | BF25: =BA25-BD25+BE25 -> 0.005424503 | BK25: =BF25-BI25+BJ25 -> 0.005424503 | BP25: =BK25-BN25+BO25 -> 0.005424503
A26: OLED_开发责 | B26: =_xlfn.IFNA(VLOOKUP($A26,批次辅助!$A$4:$DC$41,MATCH($A$5&B$4,批次辅助!$A$1:$DC$1,0),0),0) -> 0 | C26: =_xlfn.IFNA(VLOOKUP($A26,批次辅助!$A$4:$DC$41,MATCH($A$5&C$4,批次辅助!$A$1:$DC$1,0),0),0) -> 0 | D26: =_xlfn.IFNA(VLOOKUP($A26,批次辅助!$A$4:$DC$41,MATCH($A$5&D$4,批次辅助!$A$1:$DC$1,0),0),0) -> 0 | H26: =C26-F26+G26 -> 0 | M26: =H26-K26+L26 -> 0 | R26: =M26-P26+Q26 -> 0 | W26: =R26-U26+V26 -> 0 | AB26: =W26-Z26+AA26 -> 0 | AG26: =AB26-AE26+AF26 -> 0 | AL26: =AG26-AJ26+AK26 -> 0 | AQ26: =AL26-AO26+AP26 -> 0 | AV26: =AQ26-AT26+AU26 -> 0 | BA26: =AV26-AY26+AZ26 -> 0 | BF26: =BA26-BD26+BE26 -> 0 | BK26: =BF26-BI26+BJ26 -> 0 | BP26: =BK26-BN26+BO26 -> 0
A27: 风险品（OLED) | B27: =_xlfn.IFNA(VLOOKUP($A27,批次辅助!$A$4:$DC$41,MATCH($A$5&B$4,批次辅助!$A$1:$DC$1,0),0),0) -> 0 | C27: =_xlfn.IFNA(VLOOKUP($A27,批次辅助!$A$4:$DC$41,MATCH($A$5&C$4,批次辅助!$A$1:$DC$1,0),0),0) -> 0.061 | D27: =_xlfn.IFNA(VLOOKUP($A27,批次辅助!$A$4:$DC$41,MATCH($A$5&D$4,批次辅助!$A$1:$DC$1,0),0),0) -> 0 | E27: DeltaU 拦截取消 | F27: =C27 -> 0.061 | H27: =C27-F27+G27 -> 0 | M27: =H27-K27+L27 -> 0 | R27: =M27-P27+Q27 -> 0 | T27: SIH4二元化验证10Sheet | V27: =10*2/T6 -> 0.0119976 | W27: =R27-U27+V27 -> 0.0119976 | Z27: =V27 -> 0.0119976 | AB27: =W27-Z27+AA27 -> 0 | AG27: =AB27-AE27+AF27 -> 0 | AL27: =AG27-AJ27+AK27 -> 0 | AQ27: =AL27-AO27+AP27 -> 0 | AV27: =AQ27-AT27+AU27 -> 0 | BA27: =AV27-AY27+AZ27 -> 0 | BF27: =BA27-BD27+BE27 -> 0 | BK27: =BF27-BI27+BJ27 -> 0 | BP27: =BK27-BN27+BO27 -> 0
A28: 风险品（ 未分责）
A29: TP屏体 | H29: =H30*99.96% -> 0.99321224 | M29: =M30*99.96% -> 0.9953114 | R29: =R30*99.96% -> 0.9953114 | W29: =W30*99.96% -> 0.9953114 | AB29: =AB30*99.96% -> 0.9953114 | AG29: =AG30*99.96% -> 0.9953114 | AL29: =AL30*99.96% -> 0.9953114 | AQ29: =AQ30*99.96% -> 0.9953114 | AV29: =AV30*99.96% -> 0.9953114 | BA29: =BA30*99.96% -> 0.9953114 | BF29: =BF30*99.96% -> 0.9953114 | BK29: =BK30*99.96% -> 0.9953114 | BP29: =BP30*99.96% -> 0.9953114
A30: TP还原入库良率 | B30: =_xlfn.IFNA(VLOOKUP($A30,批次辅助!$A$4:$DC$41,MATCH($A$5&B$4,批次辅助!$A$1:$DC$1,0),0),0) -> 0.99434547 | C30: =_xlfn.IFNA(VLOOKUP($A30,批次辅助!$A$4:$DC$41,MATCH($A$5&C$4,批次辅助!$A$1:$DC$1,0),0),0) -> 0.99370969 | D30: =_xlfn.IFNA(VLOOKUP($A30,批次辅助!$A$4:$DC$41,MATCH($A$5&D$4,批次辅助!$A$1:$DC$1,0),0),0) -> 0.99338187 | H30: =1-SUM(H31:H35) -> 0.99360969 | M30: =1-SUM(M31:M35) -> 0.99570969 | R30: =1-SUM(R31:R35) -> 0.99570969 | W30: =1-SUM(W31:W35) -> 0.99570969 | AB30: =1-SUM(AB31:AB35) -> 0.99570969 | AG30: =1-SUM(AG31:AG35) -> 0.99570969 | AL30: =1-SUM(AL31:AL35) -> 0.99570969 | AQ30: =1-SUM(AQ31:AQ35) -> 0.99570969 | AV30: =1-SUM(AV31:AV35) -> 0.99570969 | BA30: =1-SUM(BA31:BA35) -> 0.99570969 | BF30: =1-SUM(BF31:BF35) -> 0.99570969 | BK30: =1-SUM(BK31:BK35) -> 0.99570969 | BP30: =1-SUM(BP31:BP35) -> 0.99570969
A31: TP_NG | B31: =_xlfn.IFNA(VLOOKUP($A31,批次辅助!$A$4:$DC$41,MATCH($A$5&B$4,批次辅助!$A$1:$DC$1,0),0),0) -> 0 | C31: =_xlfn.IFNA(VLOOKUP($A31,批次辅助!$A$4:$DC$41,MATCH($A$5&C$4,批次辅助!$A$1:$DC$1,0),0),0) -> 0 | D31: =_xlfn.IFNA(VLOOKUP($A31,批次辅助!$A$4:$DC$41,MATCH($A$5&D$4,批次辅助!$A$1:$DC$1,0),0),0) -> 0 | H31: =C31-F31+G31 -> 0 | M31: =H31-K31+L31 -> 0 | R31: =M31-P31+Q31 -> 0 | T31: / | W31: =R31-U31+V31 -> 0 | Y31: / | AB31: =W31-Z31+AA31 -> 0 | AD31: / | AG31: =AB31-AE31+AF31 -> 0 | AI31: / | AL31: =AG31-AJ31+AK31 -> 0 | AN31: / | AQ31: =AL31-AO31+AP31 -> 0 | AS31: / | AV31: =AQ31-AT31+AU31 -> 0 | AX31: / | BA31: =AV31-AY31+AZ31 -> 0 | BC31: / | BF31: =BA31-BD31+BE31 -> 0 | BH31: / | BK31: =BF31-BI31+BJ31 -> 0 | BM31: / | BP31: =BK31-BN31+BO31 -> 0
A32: TP_Short NG | B32: =_xlfn.IFNA(VLOOKUP($A32,批次辅助!$A$4:$DC$41,MATCH($A$5&B$4,批次辅助!$A$1:$DC$1,0),0),0) -> 0.0024738569 | C32: =_xlfn.IFNA(VLOOKUP($A32,批次辅助!$A$4:$DC$41,MATCH($A$5&C$4,批次辅助!$A$1:$DC$1,0),0),0) -> 0.0045215772 | D32: =_xlfn.IFNA(VLOOKUP($A32,批次辅助!$A$4:$DC$41,MATCH($A$5&D$4,批次辅助!$A$1:$DC$1,0),0),0) -> 0.0027299801 | E32: SHortNG改善 | F32: 0.002 | H32: =C32-F32+G32 -> 0.0025215772 | M32: =H32-K32+L32 -> 0.0025215772 | R32: =M32-P32+Q32 -> 0.0025215772 | W32: =R32-U32+V32 -> 0.0025215772 | AB32: =W32-Z32+AA32 -> 0.0025215772 | AG32: =AB32-AE32+AF32 -> 0.0025215772 | AL32: =AG32-AJ32+AK32 -> 0.0025215772 | AQ32: =AL32-AO32+AP32 -> 0.0025215772 | AV32: =AQ32-AT32+AU32 -> 0.0025215772 | BA32: =AV32-AY32+AZ32 -> 0.0025215772 | BF32: =BA32-BD32+BE32 -> 0.0025215772 | BK32: =BF32-BI32+BJ32 -> 0.0025215772 | BP32: =BK32-BN32+BO32 -> 0.0025215772
A33: TP 容值NG | B33: =_xlfn.IFNA(VLOOKUP($A33,批次辅助!$A$4:$DC$41,MATCH($A$5&B$4,批次辅助!$A$1:$DC$1,0),0),0) -> 9.0617467e-05 | C33: =_xlfn.IFNA(VLOOKUP($A33,批次辅助!$A$4:$DC$41,MATCH($A$5&C$4,批次辅助!$A$1:$DC$1,0),0),0) -> 0 | D33: =_xlfn.IFNA(VLOOKUP($A33,批次辅助!$A$4:$DC$41,MATCH($A$5&D$4,批次辅助!$A$1:$DC$1,0),0),0) -> 0.0001930289 | H33: =C33-F33+G33 -> 0 | M33: =H33-K33+L33 -> 0 | R33: =M33-P33+Q33 -> 0 | W33: =R33-U33+V33 -> 0 | AB33: =W33-Z33+AA33 -> 0 | AG33: =AB33-AE33+AF33 -> 0 | AL33: =AG33-AJ33+AK33 -> 0 | AQ33: =AL33-AO33+AP33 -> 0 | AV33: =AQ33-AT33+AU33 -> 0 | BA33: =AV33-AY33+AZ33 -> 0 | BF33: =BA33-BD33+BE33 -> 0 | BK33: =BF33-BI33+BJ33 -> 0 | BP33: =BK33-BN33+BO33 -> 0
A34: TP_RS查杀 | B34: =_xlfn.IFNA(VLOOKUP($A34,批次辅助!$A$4:$DC$41,MATCH($A$5&B$4,批次辅助!$A$1:$DC$1,0),0),0) -> 0.002038893 | C34: =_xlfn.IFNA(VLOOKUP($A34,批次辅助!$A$4:$DC$41,MATCH($A$5&C$4,批次辅助!$A$1:$DC$1,0),0),0) -> 0.0017421371 | D34: =_xlfn.IFNA(VLOOKUP($A34,批次辅助!$A$4:$DC$41,MATCH($A$5&D$4,批次辅助!$A$1:$DC$1,0),0),0) -> 0.0033090668 | E34: PHT后膜层PEELING | G34: 0.0021 | H34: =C34-F34+G34 -> 0.0038421371 | J34: PHT后膜层PEELING改善 | K34: 0.0021 | M34: =H34-K34+L34 -> 0.0017421371 | R34: =M34-P34+Q34 -> 0.0017421371 | T34: / | W34: =R34-U34+V34 -> 0.0017421371 | Y34: / | AB34: =W34-Z34+AA34 -> 0.0017421371 | AD34: / | AG34: =AB34-AE34+AF34 -> 0.0017421371 | AI34: / | AL34: =AG34-AJ34+AK34 -> 0.0017421371 | AN34: / | AQ34: =AL34-AO34+AP34 -> 0.0017421371 | AS34: / | AV34: =AQ34-AT34+AU34 -> 0.0017421371 | AX34: / | BA34: =AV34-AY34+AZ34 -> 0.0017421371 | BC34: / | BF34: =BA34-BD34+BE34 -> 0.0017421371 | BH34: / | BK34: =BF34-BI34+BJ34 -> 0.0017421371 | BM34: / | BP34: =BK34-BN34+BO34 -> 0.0017421371
A35: TP其他 | B35: =_xlfn.IFNA(VLOOKUP($A35,批次辅助!$A$4:$DC$41,MATCH($A$5&B$4,批次辅助!$A$1:$DC$1,0),0),0) -> 0.0010511626 | C35: =_xlfn.IFNA(VLOOKUP($A35,批次辅助!$A$4:$DC$41,MATCH($A$5&C$4,批次辅助!$A$1:$DC$1,0),0),0) -> 2.6597513e-05 | D35: =_xlfn.IFNA(VLOOKUP($A35,批次辅助!$A$4:$DC$41,MATCH($A$5&D$4,批次辅助!$A$1:$DC$1,0),0),0) -> 0.0003860578 | H35: =C35-F35+G35 -> 2.6597513e-05 | M35: =H35-K35+L35 -> 2.6597513e-05 | R35: =M35-P35+Q35 -> 2.6597513e-05 | T35: / | W35: =R35-U35+V35 -> 2.6597513e-05 | Y35: / | AB35: =W35-Z35+AA35 -> 2.6597513e-05 | AD35: / | AG35: =AB35-AE35+AF35 -> 2.6597513e-05 | AI35: / | AL35: =AG35-AJ35+AK35 -> 2.6597513e-05 | AN35: / | AQ35: =AL35-AO35+AP35 -> 2.6597513e-05 | AS35: / | AV35: =AQ35-AT35+AU35 -> 2.6597513e-05 | AX35: / | BA35: =AV35-AY35+AZ35 -> 2.6597513e-05 | BC35: / | BF35: =BA35-BD35+BE35 -> 2.6597513e-05 | BH35: / | BK35: =BF35-BI35+BJ35 -> 2.6597513e-05 | BM35: / | BP35: =BK35-BN35+BO35 -> 2.6597513e-05
A36: 风险品（TP) | B36: =_xlfn.IFNA(VLOOKUP($A36,批次辅助!$A$4:$DC$41,MATCH($A$5&B$4,批次辅助!$A$1:$DC$1,0),0),0) -> 0 | C36: =_xlfn.IFNA(VLOOKUP($A36,批次辅助!$A$4:$DC$41,MATCH($A$5&C$4,批次辅助!$A$1:$DC$1,0),0),0) -> 0 | D36: =_xlfn.IFNA(VLOOKUP($A36,批次辅助!$A$4:$DC$41,MATCH($A$5&D$4,批次辅助!$A$1:$DC$1,0),0),0) -> 0 | H36: =C36-F36+G36 -> 0 | M36: =H36-K36+L36 -> 0 | O36: SIH4二元化验证10Sheet | Q36: =10*2/O6 -> 0.031948882 | R36: =M36-P36+Q36 -> 0.031948882 | U36: =Q36 -> 0.031948882 | W36: =R36-U36+V36 -> 0 | AB36: =W36-Z36+AA36 -> 0 | AG36: =AB36-AE36+AF36 -> 0 | AL36: =AG36-AJ36+AK36 -> 0 | AQ36: =AL36-AO36+AP36 -> 0 | AV36: =AQ36-AT36+AU36 -> 0 | BA36: =AV36-AY36+AZ36 -> 0 | BF36: =BA36-BD36+BE36 -> 0 | BK36: =BF36-BI36+BJ36 -> 0 | BP36: =BK36-BN36+BO36 -> 0
A37: 风险品（ 未分责）
A38: 屏体良率 | H38: =H39 -> 0.99700778 | M38: =M39 -> 0.99700778 | R38: =R39 -> 0.99700778 | W38: =W39 -> 0.99700778 | AB38: =AB39 -> 0.99700778 | AG38: =AG39 -> 0.99700778 | AL38: =AL39 -> 0.99700778 | AQ38: =AQ39 -> 0.99700778 | AV38: =AV39 -> 0.99700778 | BA38: =BA39 -> 0.99700778 | BF38: =BF39 -> 0.99700778 | BK38: =BK39 -> 0.99700778 | BP38: =BP39 -> 0.99700778
